[2026-03-16T02:29:58.638+0000] {taskinstance.py:1956} INFO - Dependencies all met for dep_context=non-requeueable deps ti=<TaskInstance: brewery_data_pipeline.aggregate_gold_layer scheduled__2026-03-15T00:00:00+00:00 [queued]>
[2026-03-16T02:29:58.650+0000] {taskinstance.py:1956} INFO - Dependencies all met for dep_context=requeueable deps ti=<TaskInstance: brewery_data_pipeline.aggregate_gold_layer scheduled__2026-03-15T00:00:00+00:00 [queued]>
[2026-03-16T02:29:58.655+0000] {taskinstance.py:2170} INFO - Starting attempt 1 of 2
[2026-03-16T02:29:58.680+0000] {taskinstance.py:2191} INFO - Executing <Task(BashOperator): aggregate_gold_layer> on 2026-03-15 00:00:00+00:00
[2026-03-16T02:29:58.684+0000] {standard_task_runner.py:60} INFO - Started process 759 to run task
[2026-03-16T02:29:58.687+0000] {standard_task_runner.py:87} INFO - Running: ['***', 'tasks', 'run', 'brewery_data_pipeline', 'aggregate_gold_layer', 'scheduled__2026-03-15T00:00:00+00:00', '--job-id', '16', '--raw', '--subdir', 'DAGS_FOLDER/brewery_pipeline.py', '--cfg-path', '/tmp/tmpiajassvm']
[2026-03-16T02:29:58.689+0000] {standard_task_runner.py:88} INFO - Job 16: Subtask aggregate_gold_layer
[2026-03-16T02:29:58.707+0000] {logging_mixin.py:188} WARNING - /home/***/.local/lib/python3.8/site-packages/***/settings.py:194 DeprecationWarning: The sql_alchemy_conn option in [core] has been moved to the sql_alchemy_conn option in [database] - the old setting has been used, but please update your config.
[2026-03-16T02:29:58.769+0000] {task_command.py:423} INFO - Running <TaskInstance: brewery_data_pipeline.aggregate_gold_layer scheduled__2026-03-15T00:00:00+00:00 [running]> on host c3cb001f81d0
[2026-03-16T02:29:58.882+0000] {taskinstance.py:2480} INFO - Exporting env vars: AIRFLOW_CTX_DAG_OWNER='***' AIRFLOW_CTX_DAG_ID='brewery_data_pipeline' AIRFLOW_CTX_TASK_ID='aggregate_gold_layer' AIRFLOW_CTX_EXECUTION_DATE='2026-03-15T00:00:00+00:00' AIRFLOW_CTX_TRY_NUMBER='1' AIRFLOW_CTX_DAG_RUN_ID='scheduled__2026-03-15T00:00:00+00:00'
[2026-03-16T02:29:58.884+0000] {subprocess.py:63} INFO - Tmp dir root location: /tmp
[2026-03-16T02:29:58.885+0000] {subprocess.py:75} INFO - Running command: ['/usr/bin/bash', '-c', 'bash /opt/***/scripts/run_pyspark.sh /opt/***/scripts/aggregate_gold.py 2026-03-15']
[2026-03-16T02:29:58.896+0000] {subprocess.py:86} INFO - Output:
[2026-03-16T02:29:58.905+0000] {subprocess.py:93} INFO - --- Iniciando script PySpark: /opt/***/scripts/aggregate_gold.py para a data: 2026-03-15 ---
[2026-03-16T02:29:58.907+0000] {subprocess.py:93} INFO - Spark-Submit: Adicionando JARs ao classpath: /opt/spark/jars/hadoop-aws-3.3.4.jar,/opt/spark/jars/aws-java-sdk-bundle-1.12.672.jar,/opt/spark/jars/hadoop-common-3.3.4.jar
[2026-03-16T02:29:58.939+0000] {subprocess.py:93} INFO - /home/***/.local/lib/python3.8/site-packages/pyspark/bin/load-spark-env.sh: line 68: ps: command not found
[2026-03-16T02:30:00.866+0000] {subprocess.py:93} INFO - 26/03/16 02:30:00 WARN NativeCodeLoader: Unable to load native-hadoop library for your platform... using builtin-java classes where applicable
[2026-03-16T02:30:02.503+0000] {subprocess.py:93} INFO - 26/03/16 02:30:02 INFO SparkContext: Running Spark version 3.5.0
[2026-03-16T02:30:02.504+0000] {subprocess.py:93} INFO - 26/03/16 02:30:02 INFO SparkContext: OS info Linux, 6.6.87.2-microsoft-standard-WSL2, amd64
[2026-03-16T02:30:02.504+0000] {subprocess.py:93} INFO - 26/03/16 02:30:02 INFO SparkContext: Java version 17.0.18
[2026-03-16T02:30:02.525+0000] {subprocess.py:93} INFO - 26/03/16 02:30:02 INFO ResourceUtils: ==============================================================
[2026-03-16T02:30:02.526+0000] {subprocess.py:93} INFO - 26/03/16 02:30:02 INFO ResourceUtils: No custom resources configured for spark.driver.
[2026-03-16T02:30:02.526+0000] {subprocess.py:93} INFO - 26/03/16 02:30:02 INFO ResourceUtils: ==============================================================
[2026-03-16T02:30:02.527+0000] {subprocess.py:93} INFO - 26/03/16 02:30:02 INFO SparkContext: Submitted application: BreweryGoldLayer
[2026-03-16T02:30:02.547+0000] {subprocess.py:93} INFO - 26/03/16 02:30:02 INFO ResourceProfile: Default ResourceProfile created, executor resources: Map(cores -> name: cores, amount: 1, script: , vendor: , memory -> name: memory, amount: 1024, script: , vendor: , offHeap -> name: offHeap, amount: 0, script: , vendor: ), task resources: Map(cpus -> name: cpus, amount: 1.0)
[2026-03-16T02:30:02.552+0000] {subprocess.py:93} INFO - 26/03/16 02:30:02 INFO ResourceProfile: Limiting resource is cpu
[2026-03-16T02:30:02.553+0000] {subprocess.py:93} INFO - 26/03/16 02:30:02 INFO ResourceProfileManager: Added ResourceProfile id: 0
[2026-03-16T02:30:02.602+0000] {subprocess.py:93} INFO - 26/03/16 02:30:02 INFO SecurityManager: Changing view acls to: ***
[2026-03-16T02:30:02.603+0000] {subprocess.py:93} INFO - 26/03/16 02:30:02 INFO SecurityManager: Changing modify acls to: ***
[2026-03-16T02:30:02.603+0000] {subprocess.py:93} INFO - 26/03/16 02:30:02 INFO SecurityManager: Changing view acls groups to:
[2026-03-16T02:30:02.604+0000] {subprocess.py:93} INFO - 26/03/16 02:30:02 INFO SecurityManager: Changing modify acls groups to:
[2026-03-16T02:30:02.604+0000] {subprocess.py:93} INFO - 26/03/16 02:30:02 INFO SecurityManager: SecurityManager: authentication disabled; ui acls disabled; users with view permissions: ***; groups with view permissions: EMPTY; users with modify permissions: ***; groups with modify permissions: EMPTY
[2026-03-16T02:30:02.792+0000] {subprocess.py:93} INFO - 26/03/16 02:30:02 INFO Utils: Successfully started service 'sparkDriver' on port 43811.
[2026-03-16T02:30:02.827+0000] {subprocess.py:93} INFO - 26/03/16 02:30:02 INFO SparkEnv: Registering MapOutputTracker
[2026-03-16T02:30:02.854+0000] {subprocess.py:93} INFO - 26/03/16 02:30:02 INFO SparkEnv: Registering BlockManagerMaster
[2026-03-16T02:30:02.875+0000] {subprocess.py:93} INFO - 26/03/16 02:30:02 INFO BlockManagerMasterEndpoint: Using org.apache.spark.storage.DefaultTopologyMapper for getting topology information
[2026-03-16T02:30:02.876+0000] {subprocess.py:93} INFO - 26/03/16 02:30:02 INFO BlockManagerMasterEndpoint: BlockManagerMasterEndpoint up
[2026-03-16T02:30:02.879+0000] {subprocess.py:93} INFO - 26/03/16 02:30:02 INFO SparkEnv: Registering BlockManagerMasterHeartbeat
[2026-03-16T02:30:02.895+0000] {subprocess.py:93} INFO - 26/03/16 02:30:02 INFO DiskBlockManager: Created local directory at /tmp/blockmgr-eab9dcf9-6841-4fb3-8619-79e54bf3b53a
[2026-03-16T02:30:02.905+0000] {subprocess.py:93} INFO - 26/03/16 02:30:02 INFO MemoryStore: MemoryStore started with capacity 434.4 MiB
[2026-03-16T02:30:02.917+0000] {subprocess.py:93} INFO - 26/03/16 02:30:02 INFO SparkEnv: Registering OutputCommitCoordinator
[2026-03-16T02:30:03.026+0000] {subprocess.py:93} INFO - 26/03/16 02:30:03 INFO JettyUtils: Start Jetty 0.0.0.0:4040 for SparkUI
[2026-03-16T02:30:03.088+0000] {subprocess.py:93} INFO - 26/03/16 02:30:03 INFO Utils: Successfully started service 'SparkUI' on port 4040.
[2026-03-16T02:30:03.119+0000] {subprocess.py:93} INFO - 26/03/16 02:30:03 INFO SparkContext: Added JAR file:///opt/spark/jars/hadoop-aws-3.3.4.jar at spark://c3cb001f81d0:43811/jars/hadoop-aws-3.3.4.jar with timestamp 1773628202495
[2026-03-16T02:30:03.120+0000] {subprocess.py:93} INFO - 26/03/16 02:30:03 INFO SparkContext: Added JAR file:///opt/spark/jars/aws-java-sdk-bundle-1.12.672.jar at spark://c3cb001f81d0:43811/jars/aws-java-sdk-bundle-1.12.672.jar with timestamp 1773628202495
[2026-03-16T02:30:03.121+0000] {subprocess.py:93} INFO - 26/03/16 02:30:03 INFO SparkContext: Added JAR file:///opt/spark/jars/hadoop-common-3.3.4.jar at spark://c3cb001f81d0:43811/jars/hadoop-common-3.3.4.jar with timestamp 1773628202495
[2026-03-16T02:30:03.168+0000] {subprocess.py:93} INFO - 26/03/16 02:30:03 INFO Executor: Starting executor ID driver on host c3cb001f81d0
[2026-03-16T02:30:03.169+0000] {subprocess.py:93} INFO - 26/03/16 02:30:03 INFO Executor: OS info Linux, 6.6.87.2-microsoft-standard-WSL2, amd64
[2026-03-16T02:30:03.170+0000] {subprocess.py:93} INFO - 26/03/16 02:30:03 INFO Executor: Java version 17.0.18
[2026-03-16T02:30:03.174+0000] {subprocess.py:93} INFO - 26/03/16 02:30:03 INFO Executor: Starting executor with user classpath (userClassPathFirst = false): ''
[2026-03-16T02:30:03.175+0000] {subprocess.py:93} INFO - 26/03/16 02:30:03 INFO Executor: Created or updated repl class loader org.apache.spark.util.MutableURLClassLoader@1cefe797 for default.
[2026-03-16T02:30:03.184+0000] {subprocess.py:93} INFO - 26/03/16 02:30:03 INFO Executor: Fetching spark://c3cb001f81d0:43811/jars/aws-java-sdk-bundle-1.12.672.jar with timestamp 1773628202495
[2026-03-16T02:30:03.221+0000] {subprocess.py:93} INFO - 26/03/16 02:30:03 INFO TransportClientFactory: Successfully created connection to c3cb001f81d0/172.18.0.4:43811 after 19 ms (0 ms spent in bootstraps)
[2026-03-16T02:30:03.225+0000] {subprocess.py:93} INFO - 26/03/16 02:30:03 INFO Utils: Fetching spark://c3cb001f81d0:43811/jars/aws-java-sdk-bundle-1.12.672.jar to /tmp/spark-64c328d0-7f9b-46dd-8bc7-89e69a506569/userFiles-f160fe5b-53a7-4911-aafc-1401646919d6/fetchFileTemp12911092917503858575.tmp
[2026-03-16T02:30:05.573+0000] {subprocess.py:93} INFO - 26/03/16 02:30:05 INFO Executor: Adding file:/tmp/spark-64c328d0-7f9b-46dd-8bc7-89e69a506569/userFiles-f160fe5b-53a7-4911-aafc-1401646919d6/aws-java-sdk-bundle-1.12.672.jar to class loader default
[2026-03-16T02:30:05.575+0000] {subprocess.py:93} INFO - 26/03/16 02:30:05 INFO Executor: Fetching spark://c3cb001f81d0:43811/jars/hadoop-aws-3.3.4.jar with timestamp 1773628202495
[2026-03-16T02:30:05.575+0000] {subprocess.py:93} INFO - 26/03/16 02:30:05 INFO Utils: Fetching spark://c3cb001f81d0:43811/jars/hadoop-aws-3.3.4.jar to /tmp/spark-64c328d0-7f9b-46dd-8bc7-89e69a506569/userFiles-f160fe5b-53a7-4911-aafc-1401646919d6/fetchFileTemp17777956970543800780.tmp
[2026-03-16T02:30:05.586+0000] {subprocess.py:93} INFO - 26/03/16 02:30:05 INFO Executor: Adding file:/tmp/spark-64c328d0-7f9b-46dd-8bc7-89e69a506569/userFiles-f160fe5b-53a7-4911-aafc-1401646919d6/hadoop-aws-3.3.4.jar to class loader default
[2026-03-16T02:30:05.586+0000] {subprocess.py:93} INFO - 26/03/16 02:30:05 INFO Executor: Fetching spark://c3cb001f81d0:43811/jars/hadoop-common-3.3.4.jar with timestamp 1773628202495
[2026-03-16T02:30:05.587+0000] {subprocess.py:93} INFO - 26/03/16 02:30:05 INFO Utils: Fetching spark://c3cb001f81d0:43811/jars/hadoop-common-3.3.4.jar to /tmp/spark-64c328d0-7f9b-46dd-8bc7-89e69a506569/userFiles-f160fe5b-53a7-4911-aafc-1401646919d6/fetchFileTemp18364384049703747533.tmp
[2026-03-16T02:30:05.620+0000] {subprocess.py:93} INFO - 26/03/16 02:30:05 INFO Executor: Adding file:/tmp/spark-64c328d0-7f9b-46dd-8bc7-89e69a506569/userFiles-f160fe5b-53a7-4911-aafc-1401646919d6/hadoop-common-3.3.4.jar to class loader default
[2026-03-16T02:30:05.630+0000] {subprocess.py:93} INFO - 26/03/16 02:30:05 INFO Utils: Successfully started service 'org.apache.spark.network.netty.NettyBlockTransferService' on port 45753.
[2026-03-16T02:30:05.631+0000] {subprocess.py:93} INFO - 26/03/16 02:30:05 INFO NettyBlockTransferService: Server created on c3cb001f81d0:45753
[2026-03-16T02:30:05.632+0000] {subprocess.py:93} INFO - 26/03/16 02:30:05 INFO BlockManager: Using org.apache.spark.storage.RandomBlockReplicationPolicy for block replication policy
[2026-03-16T02:30:05.646+0000] {subprocess.py:93} INFO - 26/03/16 02:30:05 INFO BlockManagerMaster: Registering BlockManager BlockManagerId(driver, c3cb001f81d0, 45753, None)
[2026-03-16T02:30:05.652+0000] {subprocess.py:93} INFO - 26/03/16 02:30:05 INFO BlockManagerMasterEndpoint: Registering block manager c3cb001f81d0:45753 with 434.4 MiB RAM, BlockManagerId(driver, c3cb001f81d0, 45753, None)
[2026-03-16T02:30:05.655+0000] {subprocess.py:93} INFO - 26/03/16 02:30:05 INFO BlockManagerMaster: Registered BlockManager BlockManagerId(driver, c3cb001f81d0, 45753, None)
[2026-03-16T02:30:05.657+0000] {subprocess.py:93} INFO - 26/03/16 02:30:05 INFO BlockManager: Initialized BlockManager: BlockManagerId(driver, c3cb001f81d0, 45753, None)
[2026-03-16T02:30:06.089+0000] {subprocess.py:93} INFO - Gold: Lendo dados da Silver em: s3a://brewery-datalake/silver/breweries/2026-03-15
[2026-03-16T02:30:06.096+0000] {subprocess.py:93} INFO - 26/03/16 02:30:06 INFO SharedState: Setting hive.metastore.warehouse.dir ('null') to the value of spark.sql.warehouse.dir.
[2026-03-16T02:30:06.099+0000] {subprocess.py:93} INFO - 26/03/16 02:30:06 INFO SharedState: Warehouse path is 'file:/tmp/***tmp4yqlfccg/spark-warehouse'.
[2026-03-16T02:30:07.155+0000] {subprocess.py:93} INFO - 26/03/16 02:30:07 WARN MetricsConfig: Cannot locate configuration: tried hadoop-metrics2-s3a-file-system.properties,hadoop-metrics2.properties
[2026-03-16T02:30:07.165+0000] {subprocess.py:93} INFO - 26/03/16 02:30:07 INFO MetricsSystemImpl: Scheduled Metric snapshot period at 10 second(s).
[2026-03-16T02:30:07.166+0000] {subprocess.py:93} INFO - 26/03/16 02:30:07 INFO MetricsSystemImpl: s3a-file-system metrics system started
[2026-03-16T02:30:08.289+0000] {subprocess.py:93} INFO - 26/03/16 02:30:08 INFO HadoopFSUtils: Listing leaf files and directories in parallel under 137 paths. The first several paths are: s3a://brewery-datalake/silver/breweries/2026-03-15/state_province=ACT, s3a://brewery-datalake/silver/breweries/2026-03-15/state_province=Alabama, s3a://brewery-datalake/silver/breweries/2026-03-15/state_province=Alaska, s3a://brewery-datalake/silver/breweries/2026-03-15/state_province=Argyll, s3a://brewery-datalake/silver/breweries/2026-03-15/state_province=Arizona, s3a://brewery-datalake/silver/breweries/2026-03-15/state_province=Arkansas, s3a://brewery-datalake/silver/breweries/2026-03-15/state_province=Aveiro, s3a://brewery-datalake/silver/breweries/2026-03-15/state_province=Beja, s3a://brewery-datalake/silver/breweries/2026-03-15/state_province=Berlin, s3a://brewery-datalake/silver/breweries/2026-03-15/state_province=Blekinge.
[2026-03-16T02:30:08.606+0000] {subprocess.py:93} INFO - 26/03/16 02:30:08 INFO SparkContext: Starting job: parquet at NativeMethodAccessorImpl.java:0
[2026-03-16T02:30:08.619+0000] {subprocess.py:93} INFO - 26/03/16 02:30:08 INFO DAGScheduler: Got job 0 (parquet at NativeMethodAccessorImpl.java:0) with 137 output partitions
[2026-03-16T02:30:08.620+0000] {subprocess.py:93} INFO - 26/03/16 02:30:08 INFO DAGScheduler: Final stage: ResultStage 0 (parquet at NativeMethodAccessorImpl.java:0)
[2026-03-16T02:30:08.621+0000] {subprocess.py:93} INFO - 26/03/16 02:30:08 INFO DAGScheduler: Parents of final stage: List()
[2026-03-16T02:30:08.623+0000] {subprocess.py:93} INFO - 26/03/16 02:30:08 INFO DAGScheduler: Missing parents: List()
[2026-03-16T02:30:08.624+0000] {subprocess.py:93} INFO - 26/03/16 02:30:08 INFO DAGScheduler: Submitting ResultStage 0 (MapPartitionsRDD[1] at parquet at NativeMethodAccessorImpl.java:0), which has no missing parents
[2026-03-16T02:30:08.720+0000] {subprocess.py:93} INFO - 26/03/16 02:30:08 INFO MemoryStore: Block broadcast_0 stored as values in memory (estimated size 103.2 KiB, free 434.3 MiB)
[2026-03-16T02:30:08.748+0000] {subprocess.py:93} INFO - 26/03/16 02:30:08 INFO MemoryStore: Block broadcast_0_piece0 stored as bytes in memory (estimated size 37.3 KiB, free 434.3 MiB)
[2026-03-16T02:30:08.751+0000] {subprocess.py:93} INFO - 26/03/16 02:30:08 INFO BlockManagerInfo: Added broadcast_0_piece0 in memory on c3cb001f81d0:45753 (size: 37.3 KiB, free: 434.4 MiB)
[2026-03-16T02:30:08.755+0000] {subprocess.py:93} INFO - 26/03/16 02:30:08 INFO SparkContext: Created broadcast 0 from broadcast at DAGScheduler.scala:1580
[2026-03-16T02:30:08.769+0000] {subprocess.py:93} INFO - 26/03/16 02:30:08 INFO DAGScheduler: Submitting 137 missing tasks from ResultStage 0 (MapPartitionsRDD[1] at parquet at NativeMethodAccessorImpl.java:0) (first 15 tasks are for partitions Vector(0, 1, 2, 3, 4, 5, 6, 7, 8, 9, 10, 11, 12, 13, 14))
[2026-03-16T02:30:08.770+0000] {subprocess.py:93} INFO - 26/03/16 02:30:08 INFO TaskSchedulerImpl: Adding task set 0.0 with 137 tasks resource profile 0
[2026-03-16T02:30:08.831+0000] {subprocess.py:93} INFO - 26/03/16 02:30:08 INFO TaskSetManager: Starting task 0.0 in stage 0.0 (TID 0) (c3cb001f81d0, executor driver, partition 0, PROCESS_LOCAL, 8185 bytes)
[2026-03-16T02:30:08.836+0000] {subprocess.py:93} INFO - 26/03/16 02:30:08 INFO TaskSetManager: Starting task 1.0 in stage 0.0 (TID 1) (c3cb001f81d0, executor driver, partition 1, PROCESS_LOCAL, 8189 bytes)
[2026-03-16T02:30:08.837+0000] {subprocess.py:93} INFO - 26/03/16 02:30:08 INFO TaskSetManager: Starting task 2.0 in stage 0.0 (TID 2) (c3cb001f81d0, executor driver, partition 2, PROCESS_LOCAL, 8188 bytes)
[2026-03-16T02:30:08.838+0000] {subprocess.py:93} INFO - 26/03/16 02:30:08 INFO TaskSetManager: Starting task 3.0 in stage 0.0 (TID 3) (c3cb001f81d0, executor driver, partition 3, PROCESS_LOCAL, 8188 bytes)
[2026-03-16T02:30:08.838+0000] {subprocess.py:93} INFO - 26/03/16 02:30:08 INFO TaskSetManager: Starting task 4.0 in stage 0.0 (TID 4) (c3cb001f81d0, executor driver, partition 4, PROCESS_LOCAL, 8189 bytes)
[2026-03-16T02:30:08.839+0000] {subprocess.py:93} INFO - 26/03/16 02:30:08 INFO TaskSetManager: Starting task 5.0 in stage 0.0 (TID 5) (c3cb001f81d0, executor driver, partition 5, PROCESS_LOCAL, 8190 bytes)
[2026-03-16T02:30:08.840+0000] {subprocess.py:93} INFO - 26/03/16 02:30:08 INFO TaskSetManager: Starting task 6.0 in stage 0.0 (TID 6) (c3cb001f81d0, executor driver, partition 6, PROCESS_LOCAL, 8188 bytes)
[2026-03-16T02:30:08.841+0000] {subprocess.py:93} INFO - 26/03/16 02:30:08 INFO TaskSetManager: Starting task 7.0 in stage 0.0 (TID 7) (c3cb001f81d0, executor driver, partition 7, PROCESS_LOCAL, 8186 bytes)
[2026-03-16T02:30:08.841+0000] {subprocess.py:93} INFO - 26/03/16 02:30:08 INFO TaskSetManager: Starting task 8.0 in stage 0.0 (TID 8) (c3cb001f81d0, executor driver, partition 8, PROCESS_LOCAL, 8188 bytes)
[2026-03-16T02:30:08.842+0000] {subprocess.py:93} INFO - 26/03/16 02:30:08 INFO TaskSetManager: Starting task 9.0 in stage 0.0 (TID 9) (c3cb001f81d0, executor driver, partition 9, PROCESS_LOCAL, 8190 bytes)
[2026-03-16T02:30:08.842+0000] {subprocess.py:93} INFO - 26/03/16 02:30:08 INFO TaskSetManager: Starting task 10.0 in stage 0.0 (TID 10) (c3cb001f81d0, executor driver, partition 10, PROCESS_LOCAL, 8189 bytes)
[2026-03-16T02:30:08.843+0000] {subprocess.py:93} INFO - 26/03/16 02:30:08 INFO TaskSetManager: Starting task 11.0 in stage 0.0 (TID 11) (c3cb001f81d0, executor driver, partition 11, PROCESS_LOCAL, 8202 bytes)
[2026-03-16T02:30:08.856+0000] {subprocess.py:93} INFO - 26/03/16 02:30:08 INFO Executor: Running task 1.0 in stage 0.0 (TID 1)
[2026-03-16T02:30:08.857+0000] {subprocess.py:93} INFO - 26/03/16 02:30:08 INFO Executor: Running task 10.0 in stage 0.0 (TID 10)
[2026-03-16T02:30:08.858+0000] {subprocess.py:93} INFO - 26/03/16 02:30:08 INFO Executor: Running task 7.0 in stage 0.0 (TID 7)
[2026-03-16T02:30:08.858+0000] {subprocess.py:93} INFO - 26/03/16 02:30:08 INFO Executor: Running task 9.0 in stage 0.0 (TID 9)
[2026-03-16T02:30:08.860+0000] {subprocess.py:93} INFO - 26/03/16 02:30:08 INFO Executor: Running task 2.0 in stage 0.0 (TID 2)
[2026-03-16T02:30:08.863+0000] {subprocess.py:93} INFO - 26/03/16 02:30:08 INFO Executor: Running task 3.0 in stage 0.0 (TID 3)
[2026-03-16T02:30:08.863+0000] {subprocess.py:93} INFO - 26/03/16 02:30:08 INFO Executor: Running task 6.0 in stage 0.0 (TID 6)
[2026-03-16T02:30:08.864+0000] {subprocess.py:93} INFO - 26/03/16 02:30:08 INFO Executor: Running task 4.0 in stage 0.0 (TID 4)
[2026-03-16T02:30:08.865+0000] {subprocess.py:93} INFO - 26/03/16 02:30:08 INFO Executor: Running task 8.0 in stage 0.0 (TID 8)
[2026-03-16T02:30:08.865+0000] {subprocess.py:93} INFO - 26/03/16 02:30:08 INFO Executor: Running task 5.0 in stage 0.0 (TID 5)
[2026-03-16T02:30:08.866+0000] {subprocess.py:93} INFO - 26/03/16 02:30:08 INFO Executor: Running task 0.0 in stage 0.0 (TID 0)
[2026-03-16T02:30:08.867+0000] {subprocess.py:93} INFO - 26/03/16 02:30:08 INFO Executor: Running task 11.0 in stage 0.0 (TID 11)
[2026-03-16T02:30:09.151+0000] {subprocess.py:93} INFO - 26/03/16 02:30:09 INFO Executor: Finished task 5.0 in stage 0.0 (TID 5). 3103 bytes result sent to driver
[2026-03-16T02:30:09.152+0000] {subprocess.py:93} INFO - 26/03/16 02:30:09 INFO Executor: Finished task 1.0 in stage 0.0 (TID 1). 3143 bytes result sent to driver
[2026-03-16T02:30:09.154+0000] {subprocess.py:93} INFO - 26/03/16 02:30:09 INFO Executor: Finished task 3.0 in stage 0.0 (TID 3). 3097 bytes result sent to driver
[2026-03-16T02:30:09.156+0000] {subprocess.py:93} INFO - 26/03/16 02:30:09 INFO Executor: Finished task 10.0 in stage 0.0 (TID 10). 3143 bytes result sent to driver
[2026-03-16T02:30:09.156+0000] {subprocess.py:93} INFO - 26/03/16 02:30:09 INFO Executor: Finished task 4.0 in stage 0.0 (TID 4). 3143 bytes result sent to driver
[2026-03-16T02:30:09.157+0000] {subprocess.py:93} INFO - 26/03/16 02:30:09 INFO Executor: Finished task 2.0 in stage 0.0 (TID 2). 3097 bytes result sent to driver
[2026-03-16T02:30:09.158+0000] {subprocess.py:93} INFO - 26/03/16 02:30:09 INFO Executor: Finished task 0.0 in stage 0.0 (TID 0). 3131 bytes result sent to driver
[2026-03-16T02:30:09.159+0000] {subprocess.py:93} INFO - 26/03/16 02:30:09 INFO Executor: Finished task 6.0 in stage 0.0 (TID 6). 3140 bytes result sent to driver
[2026-03-16T02:30:09.160+0000] {subprocess.py:93} INFO - 26/03/16 02:30:09 INFO Executor: Finished task 8.0 in stage 0.0 (TID 8). 3140 bytes result sent to driver
[2026-03-16T02:30:09.161+0000] {subprocess.py:93} INFO - 26/03/16 02:30:09 INFO Executor: Finished task 9.0 in stage 0.0 (TID 9). 3103 bytes result sent to driver
[2026-03-16T02:30:09.161+0000] {subprocess.py:93} INFO - 26/03/16 02:30:09 INFO Executor: Finished task 7.0 in stage 0.0 (TID 7). 2808 bytes result sent to driver
[2026-03-16T02:30:09.162+0000] {subprocess.py:93} INFO - 26/03/16 02:30:09 INFO Executor: Finished task 11.0 in stage 0.0 (TID 11). 3139 bytes result sent to driver
[2026-03-16T02:30:09.163+0000] {subprocess.py:93} INFO - 26/03/16 02:30:09 INFO TaskSetManager: Starting task 12.0 in stage 0.0 (TID 12) (c3cb001f81d0, executor driver, partition 12, PROCESS_LOCAL, 8200 bytes)
[2026-03-16T02:30:09.164+0000] {subprocess.py:93} INFO - 26/03/16 02:30:09 INFO Executor: Running task 12.0 in stage 0.0 (TID 12)
[2026-03-16T02:30:09.165+0000] {subprocess.py:93} INFO - 26/03/16 02:30:09 INFO TaskSetManager: Starting task 13.0 in stage 0.0 (TID 13) (c3cb001f81d0, executor driver, partition 13, PROCESS_LOCAL, 8187 bytes)
[2026-03-16T02:30:09.166+0000] {subprocess.py:93} INFO - 26/03/16 02:30:09 INFO Executor: Running task 13.0 in stage 0.0 (TID 13)
[2026-03-16T02:30:09.168+0000] {subprocess.py:93} INFO - 26/03/16 02:30:09 INFO TaskSetManager: Starting task 14.0 in stage 0.0 (TID 14) (c3cb001f81d0, executor driver, partition 14, PROCESS_LOCAL, 8186 bytes)
[2026-03-16T02:30:09.169+0000] {subprocess.py:93} INFO - 26/03/16 02:30:09 INFO Executor: Running task 14.0 in stage 0.0 (TID 14)
[2026-03-16T02:30:09.169+0000] {subprocess.py:93} INFO - 26/03/16 02:30:09 INFO TaskSetManager: Starting task 15.0 in stage 0.0 (TID 15) (c3cb001f81d0, executor driver, partition 15, PROCESS_LOCAL, 8192 bytes)
[2026-03-16T02:30:09.170+0000] {subprocess.py:93} INFO - 26/03/16 02:30:09 INFO Executor: Running task 15.0 in stage 0.0 (TID 15)
[2026-03-16T02:30:09.171+0000] {subprocess.py:93} INFO - 26/03/16 02:30:09 INFO TaskSetManager: Finished task 11.0 in stage 0.0 (TID 11) in 325 ms on c3cb001f81d0 (executor driver) (1/137)
[2026-03-16T02:30:09.172+0000] {subprocess.py:93} INFO - 26/03/16 02:30:09 INFO TaskSetManager: Starting task 16.0 in stage 0.0 (TID 16) (c3cb001f81d0, executor driver, partition 16, PROCESS_LOCAL, 8188 bytes)
[2026-03-16T02:30:09.173+0000] {subprocess.py:93} INFO - 26/03/16 02:30:09 INFO TaskSetManager: Finished task 6.0 in stage 0.0 (TID 6) in 332 ms on c3cb001f81d0 (executor driver) (2/137)
[2026-03-16T02:30:09.178+0000] {subprocess.py:93} INFO - 26/03/16 02:30:09 INFO Executor: Running task 16.0 in stage 0.0 (TID 16)
[2026-03-16T02:30:09.179+0000] {subprocess.py:93} INFO - 26/03/16 02:30:09 INFO TaskSetManager: Finished task 8.0 in stage 0.0 (TID 8) in 331 ms on c3cb001f81d0 (executor driver) (3/137)
[2026-03-16T02:30:09.180+0000] {subprocess.py:93} INFO - 26/03/16 02:30:09 INFO TaskSetManager: Finished task 1.0 in stage 0.0 (TID 1) in 338 ms on c3cb001f81d0 (executor driver) (4/137)
[2026-03-16T02:30:09.183+0000] {subprocess.py:93} INFO - 26/03/16 02:30:09 INFO TaskSetManager: Starting task 17.0 in stage 0.0 (TID 17) (c3cb001f81d0, executor driver, partition 17, PROCESS_LOCAL, 8198 bytes)
[2026-03-16T02:30:09.184+0000] {subprocess.py:93} INFO - 26/03/16 02:30:09 INFO TaskSetManager: Finished task 0.0 in stage 0.0 (TID 0) in 368 ms on c3cb001f81d0 (executor driver) (5/137)
[2026-03-16T02:30:09.186+0000] {subprocess.py:93} INFO - 26/03/16 02:30:09 INFO Executor: Running task 17.0 in stage 0.0 (TID 17)
[2026-03-16T02:30:09.189+0000] {subprocess.py:93} INFO - 26/03/16 02:30:09 INFO TaskSetManager: Finished task 4.0 in stage 0.0 (TID 4) in 341 ms on c3cb001f81d0 (executor driver) (6/137)
[2026-03-16T02:30:09.191+0000] {subprocess.py:93} INFO - 26/03/16 02:30:09 INFO TaskSetManager: Starting task 18.0 in stage 0.0 (TID 18) (c3cb001f81d0, executor driver, partition 18, PROCESS_LOCAL, 8198 bytes)
[2026-03-16T02:30:09.194+0000] {subprocess.py:93} INFO - 26/03/16 02:30:09 INFO Executor: Running task 18.0 in stage 0.0 (TID 18)
[2026-03-16T02:30:09.195+0000] {subprocess.py:93} INFO - 26/03/16 02:30:09 INFO TaskSetManager: Starting task 19.0 in stage 0.0 (TID 19) (c3cb001f81d0, executor driver, partition 19, PROCESS_LOCAL, 8187 bytes)
[2026-03-16T02:30:09.197+0000] {subprocess.py:93} INFO - 26/03/16 02:30:09 INFO TaskSetManager: Starting task 20.0 in stage 0.0 (TID 20) (c3cb001f81d0, executor driver, partition 20, PROCESS_LOCAL, 8189 bytes)
[2026-03-16T02:30:09.204+0000] {subprocess.py:93} INFO - 26/03/16 02:30:09 INFO Executor: Running task 20.0 in stage 0.0 (TID 20)
[2026-03-16T02:30:09.206+0000] {subprocess.py:93} INFO - 26/03/16 02:30:09 INFO Executor: Running task 19.0 in stage 0.0 (TID 19)
[2026-03-16T02:30:09.210+0000] {subprocess.py:93} INFO - 26/03/16 02:30:09 INFO TaskSetManager: Starting task 21.0 in stage 0.0 (TID 21) (c3cb001f81d0, executor driver, partition 21, PROCESS_LOCAL, 8190 bytes)
[2026-03-16T02:30:09.218+0000] {subprocess.py:93} INFO - 26/03/16 02:30:09 INFO Executor: Finished task 13.0 in stage 0.0 (TID 13). 3051 bytes result sent to driver
[2026-03-16T02:30:09.219+0000] {subprocess.py:93} INFO - 26/03/16 02:30:09 INFO Executor: Running task 21.0 in stage 0.0 (TID 21)
[2026-03-16T02:30:09.220+0000] {subprocess.py:93} INFO - 26/03/16 02:30:09 INFO TaskSetManager: Starting task 22.0 in stage 0.0 (TID 22) (c3cb001f81d0, executor driver, partition 22, PROCESS_LOCAL, 8193 bytes)
[2026-03-16T02:30:09.223+0000] {subprocess.py:93} INFO - 26/03/16 02:30:09 INFO Executor: Finished task 14.0 in stage 0.0 (TID 14). 2722 bytes result sent to driver
[2026-03-16T02:30:09.224+0000] {subprocess.py:93} INFO - 26/03/16 02:30:09 INFO Executor: Running task 22.0 in stage 0.0 (TID 22)
[2026-03-16T02:30:09.227+0000] {subprocess.py:93} INFO - 26/03/16 02:30:09 INFO TaskSetManager: Finished task 3.0 in stage 0.0 (TID 3) in 361 ms on c3cb001f81d0 (executor driver) (7/137)
[2026-03-16T02:30:09.228+0000] {subprocess.py:93} INFO - 26/03/16 02:30:09 INFO TaskSetManager: Finished task 9.0 in stage 0.0 (TID 9) in 356 ms on c3cb001f81d0 (executor driver) (8/137)
[2026-03-16T02:30:09.229+0000] {subprocess.py:93} INFO - 26/03/16 02:30:09 INFO TaskSetManager: Finished task 7.0 in stage 0.0 (TID 7) in 358 ms on c3cb001f81d0 (executor driver) (9/137)
[2026-03-16T02:30:09.230+0000] {subprocess.py:93} INFO - 26/03/16 02:30:09 INFO TaskSetManager: Finished task 2.0 in stage 0.0 (TID 2) in 363 ms on c3cb001f81d0 (executor driver) (10/137)
[2026-03-16T02:30:09.231+0000] {subprocess.py:93} INFO - 26/03/16 02:30:09 INFO TaskSetManager: Finished task 10.0 in stage 0.0 (TID 10) in 357 ms on c3cb001f81d0 (executor driver) (11/137)
[2026-03-16T02:30:09.232+0000] {subprocess.py:93} INFO - 26/03/16 02:30:09 INFO Executor: Finished task 15.0 in stage 0.0 (TID 15). 3109 bytes result sent to driver
[2026-03-16T02:30:09.235+0000] {subprocess.py:93} INFO - 26/03/16 02:30:09 INFO TaskSetManager: Finished task 5.0 in stage 0.0 (TID 5) in 362 ms on c3cb001f81d0 (executor driver) (12/137)
[2026-03-16T02:30:09.236+0000] {subprocess.py:93} INFO - 26/03/16 02:30:09 INFO Executor: Finished task 12.0 in stage 0.0 (TID 12). 3090 bytes result sent to driver
[2026-03-16T02:30:09.237+0000] {subprocess.py:93} INFO - 26/03/16 02:30:09 INFO TaskSetManager: Starting task 23.0 in stage 0.0 (TID 23) (c3cb001f81d0, executor driver, partition 23, PROCESS_LOCAL, 8186 bytes)
[2026-03-16T02:30:09.237+0000] {subprocess.py:93} INFO - 26/03/16 02:30:09 INFO TaskSetManager: Starting task 24.0 in stage 0.0 (TID 24) (c3cb001f81d0, executor driver, partition 24, PROCESS_LOCAL, 8189 bytes)
[2026-03-16T02:30:09.238+0000] {subprocess.py:93} INFO - 26/03/16 02:30:09 INFO Executor: Running task 23.0 in stage 0.0 (TID 23)
[2026-03-16T02:30:09.242+0000] {subprocess.py:93} INFO - 26/03/16 02:30:09 INFO TaskSetManager: Starting task 25.0 in stage 0.0 (TID 25) (c3cb001f81d0, executor driver, partition 25, PROCESS_LOCAL, 8187 bytes)
[2026-03-16T02:30:09.243+0000] {subprocess.py:93} INFO - 26/03/16 02:30:09 INFO TaskSetManager: Starting task 26.0 in stage 0.0 (TID 26) (c3cb001f81d0, executor driver, partition 26, PROCESS_LOCAL, 8190 bytes)
[2026-03-16T02:30:09.244+0000] {subprocess.py:93} INFO - 26/03/16 02:30:09 INFO Executor: Running task 25.0 in stage 0.0 (TID 25)
[2026-03-16T02:30:09.247+0000] {subprocess.py:93} INFO - 26/03/16 02:30:09 INFO TaskSetManager: Starting task 27.0 in stage 0.0 (TID 27) (c3cb001f81d0, executor driver, partition 27, PROCESS_LOCAL, 8206 bytes)
[2026-03-16T02:30:09.249+0000] {subprocess.py:93} INFO - 26/03/16 02:30:09 INFO Executor: Running task 24.0 in stage 0.0 (TID 24)
[2026-03-16T02:30:09.251+0000] {subprocess.py:93} INFO - 26/03/16 02:30:09 INFO TaskSetManager: Finished task 13.0 in stage 0.0 (TID 13) in 50 ms on c3cb001f81d0 (executor driver) (13/137)
[2026-03-16T02:30:09.258+0000] {subprocess.py:93} INFO - 26/03/16 02:30:09 INFO Executor: Running task 27.0 in stage 0.0 (TID 27)
[2026-03-16T02:30:09.259+0000] {subprocess.py:93} INFO - 26/03/16 02:30:09 INFO Executor: Running task 26.0 in stage 0.0 (TID 26)
[2026-03-16T02:30:09.259+0000] {subprocess.py:93} INFO - 26/03/16 02:30:09 INFO TaskSetManager: Finished task 12.0 in stage 0.0 (TID 12) in 61 ms on c3cb001f81d0 (executor driver) (14/137)
[2026-03-16T02:30:09.260+0000] {subprocess.py:93} INFO - 26/03/16 02:30:09 INFO TaskSetManager: Finished task 15.0 in stage 0.0 (TID 15) in 55 ms on c3cb001f81d0 (executor driver) (15/137)
[2026-03-16T02:30:09.261+0000] {subprocess.py:93} INFO - 26/03/16 02:30:09 INFO Executor: Finished task 16.0 in stage 0.0 (TID 16). 2812 bytes result sent to driver
[2026-03-16T02:30:09.266+0000] {subprocess.py:93} INFO - 26/03/16 02:30:09 INFO Executor: Finished task 17.0 in stage 0.0 (TID 17). 2789 bytes result sent to driver
[2026-03-16T02:30:09.267+0000] {subprocess.py:93} INFO - 26/03/16 02:30:09 INFO Executor: Finished task 20.0 in stage 0.0 (TID 20). 2771 bytes result sent to driver
[2026-03-16T02:30:09.268+0000] {subprocess.py:93} INFO - 26/03/16 02:30:09 INFO TaskSetManager: Starting task 28.0 in stage 0.0 (TID 28) (c3cb001f81d0, executor driver, partition 28, PROCESS_LOCAL, 8205 bytes)
[2026-03-16T02:30:09.268+0000] {subprocess.py:93} INFO - 26/03/16 02:30:09 INFO TaskSetManager: Finished task 14.0 in stage 0.0 (TID 14) in 86 ms on c3cb001f81d0 (executor driver) (16/137)
[2026-03-16T02:30:09.269+0000] {subprocess.py:93} INFO - 26/03/16 02:30:09 INFO TaskSetManager: Finished task 16.0 in stage 0.0 (TID 16) in 79 ms on c3cb001f81d0 (executor driver) (17/137)
[2026-03-16T02:30:09.271+0000] {subprocess.py:93} INFO - 26/03/16 02:30:09 INFO TaskSetManager: Starting task 29.0 in stage 0.0 (TID 29) (c3cb001f81d0, executor driver, partition 29, PROCESS_LOCAL, 8189 bytes)
[2026-03-16T02:30:09.272+0000] {subprocess.py:93} INFO - 26/03/16 02:30:09 INFO Executor: Finished task 21.0 in stage 0.0 (TID 21). 3103 bytes result sent to driver
[2026-03-16T02:30:09.273+0000] {subprocess.py:93} INFO - 26/03/16 02:30:09 INFO TaskSetManager: Starting task 30.0 in stage 0.0 (TID 30) (c3cb001f81d0, executor driver, partition 30, PROCESS_LOCAL, 8188 bytes)
[2026-03-16T02:30:09.273+0000] {subprocess.py:93} INFO - 26/03/16 02:30:09 INFO Executor: Running task 28.0 in stage 0.0 (TID 28)
[2026-03-16T02:30:09.278+0000] {subprocess.py:93} INFO - 26/03/16 02:30:09 INFO Executor: Running task 29.0 in stage 0.0 (TID 29)
[2026-03-16T02:30:09.279+0000] {subprocess.py:93} INFO - 26/03/16 02:30:09 INFO TaskSetManager: Starting task 31.0 in stage 0.0 (TID 31) (c3cb001f81d0, executor driver, partition 31, PROCESS_LOCAL, 8203 bytes)
[2026-03-16T02:30:09.279+0000] {subprocess.py:93} INFO - 26/03/16 02:30:09 INFO Executor: Running task 30.0 in stage 0.0 (TID 30)
[2026-03-16T02:30:09.282+0000] {subprocess.py:93} INFO - 26/03/16 02:30:09 INFO Executor: Finished task 18.0 in stage 0.0 (TID 18). 3127 bytes result sent to driver
[2026-03-16T02:30:09.290+0000] {subprocess.py:93} INFO - 26/03/16 02:30:09 INFO TaskSetManager: Finished task 21.0 in stage 0.0 (TID 21) in 70 ms on c3cb001f81d0 (executor driver) (18/137)
[2026-03-16T02:30:09.294+0000] {subprocess.py:93} INFO - 26/03/16 02:30:09 INFO Executor: Running task 31.0 in stage 0.0 (TID 31)
[2026-03-16T02:30:09.295+0000] {subprocess.py:93} INFO - 26/03/16 02:30:09 INFO TaskSetManager: Starting task 32.0 in stage 0.0 (TID 32) (c3cb001f81d0, executor driver, partition 32, PROCESS_LOCAL, 8195 bytes)
[2026-03-16T02:30:09.298+0000] {subprocess.py:93} INFO - 26/03/16 02:30:09 INFO TaskSetManager: Finished task 17.0 in stage 0.0 (TID 17) in 85 ms on c3cb001f81d0 (executor driver) (19/137)
[2026-03-16T02:30:09.299+0000] {subprocess.py:93} INFO - 26/03/16 02:30:09 INFO Executor: Finished task 27.0 in stage 0.0 (TID 27). 3154 bytes result sent to driver
[2026-03-16T02:30:09.300+0000] {subprocess.py:93} INFO - 26/03/16 02:30:09 INFO Executor: Finished task 22.0 in stage 0.0 (TID 22). 3112 bytes result sent to driver
[2026-03-16T02:30:09.300+0000] {subprocess.py:93} INFO - 26/03/16 02:30:09 INFO Executor: Finished task 19.0 in stage 0.0 (TID 19). 2810 bytes result sent to driver
[2026-03-16T02:30:09.301+0000] {subprocess.py:93} INFO - 26/03/16 02:30:09 INFO Executor: Running task 32.0 in stage 0.0 (TID 32)
[2026-03-16T02:30:09.302+0000] {subprocess.py:93} INFO - 26/03/16 02:30:09 INFO Executor: Finished task 23.0 in stage 0.0 (TID 23). 3091 bytes result sent to driver
[2026-03-16T02:30:09.309+0000] {subprocess.py:93} INFO - 26/03/16 02:30:09 INFO TaskSetManager: Finished task 18.0 in stage 0.0 (TID 18) in 83 ms on c3cb001f81d0 (executor driver) (20/137)
[2026-03-16T02:30:09.310+0000] {subprocess.py:93} INFO - 26/03/16 02:30:09 INFO TaskSetManager: Finished task 20.0 in stage 0.0 (TID 20) in 95 ms on c3cb001f81d0 (executor driver) (21/137)
[2026-03-16T02:30:09.311+0000] {subprocess.py:93} INFO - 26/03/16 02:30:09 INFO TaskSetManager: Starting task 33.0 in stage 0.0 (TID 33) (c3cb001f81d0, executor driver, partition 33, PROCESS_LOCAL, 8196 bytes)
[2026-03-16T02:30:09.313+0000] {subprocess.py:93} INFO - 26/03/16 02:30:09 INFO TaskSetManager: Starting task 34.0 in stage 0.0 (TID 34) (c3cb001f81d0, executor driver, partition 34, PROCESS_LOCAL, 8186 bytes)
[2026-03-16T02:30:09.318+0000] {subprocess.py:93} INFO - 26/03/16 02:30:09 INFO Executor: Running task 33.0 in stage 0.0 (TID 33)
[2026-03-16T02:30:09.319+0000] {subprocess.py:93} INFO - 26/03/16 02:30:09 INFO Executor: Finished task 25.0 in stage 0.0 (TID 25). 2767 bytes result sent to driver
[2026-03-16T02:30:09.321+0000] {subprocess.py:93} INFO - 26/03/16 02:30:09 INFO TaskSetManager: Finished task 23.0 in stage 0.0 (TID 23) in 87 ms on c3cb001f81d0 (executor driver) (22/137)
[2026-03-16T02:30:09.330+0000] {subprocess.py:93} INFO - 26/03/16 02:30:09 INFO TaskSetManager: Finished task 19.0 in stage 0.0 (TID 19) in 109 ms on c3cb001f81d0 (executor driver) (23/137)
[2026-03-16T02:30:09.331+0000] {subprocess.py:93} INFO - 26/03/16 02:30:09 INFO Executor: Finished task 26.0 in stage 0.0 (TID 26). 3103 bytes result sent to driver
[2026-03-16T02:30:09.333+0000] {subprocess.py:93} INFO - 26/03/16 02:30:09 INFO Executor: Running task 34.0 in stage 0.0 (TID 34)
[2026-03-16T02:30:09.335+0000] {subprocess.py:93} INFO - 26/03/16 02:30:09 INFO Executor: Finished task 24.0 in stage 0.0 (TID 24). 2771 bytes result sent to driver
[2026-03-16T02:30:09.336+0000] {subprocess.py:93} INFO - 26/03/16 02:30:09 INFO TaskSetManager: Starting task 35.0 in stage 0.0 (TID 35) (c3cb001f81d0, executor driver, partition 35, PROCESS_LOCAL, 8189 bytes)
[2026-03-16T02:30:09.349+0000] {subprocess.py:93} INFO - 26/03/16 02:30:09 INFO Executor: Running task 35.0 in stage 0.0 (TID 35)
[2026-03-16T02:30:09.393+0000] {subprocess.py:93} INFO - 26/03/16 02:30:09 INFO TaskSetManager: Starting task 36.0 in stage 0.0 (TID 36) (c3cb001f81d0, executor driver, partition 36, PROCESS_LOCAL, 8194 bytes)
[2026-03-16T02:30:09.394+0000] {subprocess.py:93} INFO - 26/03/16 02:30:09 INFO TaskSetManager: Starting task 37.0 in stage 0.0 (TID 37) (c3cb001f81d0, executor driver, partition 37, PROCESS_LOCAL, 8188 bytes)
[2026-03-16T02:30:09.394+0000] {subprocess.py:93} INFO - 26/03/16 02:30:09 INFO Executor: Running task 36.0 in stage 0.0 (TID 36)
[2026-03-16T02:30:09.394+0000] {subprocess.py:93} INFO - 26/03/16 02:30:09 INFO TaskSetManager: Starting task 38.0 in stage 0.0 (TID 38) (c3cb001f81d0, executor driver, partition 38, PROCESS_LOCAL, 8191 bytes)
[2026-03-16T02:30:09.395+0000] {subprocess.py:93} INFO - 26/03/16 02:30:09 INFO TaskSetManager: Finished task 27.0 in stage 0.0 (TID 27) in 96 ms on c3cb001f81d0 (executor driver) (24/137)
[2026-03-16T02:30:09.395+0000] {subprocess.py:93} INFO - 26/03/16 02:30:09 INFO TaskSetManager: Finished task 25.0 in stage 0.0 (TID 25) in 100 ms on c3cb001f81d0 (executor driver) (25/137)
[2026-03-16T02:30:09.396+0000] {subprocess.py:93} INFO - 26/03/16 02:30:09 INFO TaskSetManager: Finished task 26.0 in stage 0.0 (TID 26) in 101 ms on c3cb001f81d0 (executor driver) (26/137)
[2026-03-16T02:30:09.396+0000] {subprocess.py:93} INFO - 26/03/16 02:30:09 INFO Executor: Running task 37.0 in stage 0.0 (TID 37)
[2026-03-16T02:30:09.397+0000] {subprocess.py:93} INFO - 26/03/16 02:30:09 INFO Executor: Running task 38.0 in stage 0.0 (TID 38)
[2026-03-16T02:30:09.397+0000] {subprocess.py:93} INFO - 26/03/16 02:30:09 INFO TaskSetManager: Starting task 39.0 in stage 0.0 (TID 39) (c3cb001f81d0, executor driver, partition 39, PROCESS_LOCAL, 8189 bytes)
[2026-03-16T02:30:09.397+0000] {subprocess.py:93} INFO - 26/03/16 02:30:09 INFO Executor: Finished task 28.0 in stage 0.0 (TID 28). 2760 bytes result sent to driver
[2026-03-16T02:30:09.398+0000] {subprocess.py:93} INFO - 26/03/16 02:30:09 INFO TaskSetManager: Finished task 24.0 in stage 0.0 (TID 24) in 112 ms on c3cb001f81d0 (executor driver) (27/137)
[2026-03-16T02:30:09.398+0000] {subprocess.py:93} INFO - 26/03/16 02:30:09 INFO TaskSetManager: Finished task 22.0 in stage 0.0 (TID 22) in 123 ms on c3cb001f81d0 (executor driver) (28/137)
[2026-03-16T02:30:09.399+0000] {subprocess.py:93} INFO - 26/03/16 02:30:09 INFO Executor: Finished task 30.0 in stage 0.0 (TID 30). 3054 bytes result sent to driver
[2026-03-16T02:30:09.399+0000] {subprocess.py:93} INFO - 26/03/16 02:30:09 INFO Executor: Running task 39.0 in stage 0.0 (TID 39)
[2026-03-16T02:30:09.399+0000] {subprocess.py:93} INFO - 26/03/16 02:30:09 INFO Executor: Finished task 31.0 in stage 0.0 (TID 31). 2756 bytes result sent to driver
[2026-03-16T02:30:09.399+0000] {subprocess.py:93} INFO - 26/03/16 02:30:09 INFO TaskSetManager: Starting task 40.0 in stage 0.0 (TID 40) (c3cb001f81d0, executor driver, partition 40, PROCESS_LOCAL, 8189 bytes)
[2026-03-16T02:30:09.400+0000] {subprocess.py:93} INFO - 26/03/16 02:30:09 INFO TaskSetManager: Starting task 41.0 in stage 0.0 (TID 41) (c3cb001f81d0, executor driver, partition 41, PROCESS_LOCAL, 8189 bytes)
[2026-03-16T02:30:09.400+0000] {subprocess.py:93} INFO - 26/03/16 02:30:09 INFO TaskSetManager: Starting task 42.0 in stage 0.0 (TID 42) (c3cb001f81d0, executor driver, partition 42, PROCESS_LOCAL, 8192 bytes)
[2026-03-16T02:30:09.400+0000] {subprocess.py:93} INFO - 26/03/16 02:30:09 INFO Executor: Running task 40.0 in stage 0.0 (TID 40)
[2026-03-16T02:30:09.401+0000] {subprocess.py:93} INFO - 26/03/16 02:30:09 INFO Executor: Finished task 29.0 in stage 0.0 (TID 29). 3057 bytes result sent to driver
[2026-03-16T02:30:09.401+0000] {subprocess.py:93} INFO - 26/03/16 02:30:09 INFO TaskSetManager: Starting task 43.0 in stage 0.0 (TID 43) (c3cb001f81d0, executor driver, partition 43, PROCESS_LOCAL, 8197 bytes)
[2026-03-16T02:30:09.401+0000] {subprocess.py:93} INFO - 26/03/16 02:30:09 INFO Executor: Running task 41.0 in stage 0.0 (TID 41)
[2026-03-16T02:30:09.402+0000] {subprocess.py:93} INFO - 26/03/16 02:30:09 INFO TaskSetManager: Finished task 28.0 in stage 0.0 (TID 28) in 85 ms on c3cb001f81d0 (executor driver) (29/137)
[2026-03-16T02:30:09.402+0000] {subprocess.py:93} INFO - 26/03/16 02:30:09 INFO TaskSetManager: Finished task 29.0 in stage 0.0 (TID 29) in 78 ms on c3cb001f81d0 (executor driver) (30/137)
[2026-03-16T02:30:09.402+0000] {subprocess.py:93} INFO - 26/03/16 02:30:09 INFO TaskSetManager: Finished task 31.0 in stage 0.0 (TID 31) in 75 ms on c3cb001f81d0 (executor driver) (31/137)
[2026-03-16T02:30:09.403+0000] {subprocess.py:93} INFO - 26/03/16 02:30:09 INFO Executor: Running task 42.0 in stage 0.0 (TID 42)
[2026-03-16T02:30:09.403+0000] {subprocess.py:93} INFO - 26/03/16 02:30:09 INFO Executor: Finished task 34.0 in stage 0.0 (TID 34). 2722 bytes result sent to driver
[2026-03-16T02:30:09.403+0000] {subprocess.py:93} INFO - 26/03/16 02:30:09 INFO TaskSetManager: Starting task 44.0 in stage 0.0 (TID 44) (c3cb001f81d0, executor driver, partition 44, PROCESS_LOCAL, 8197 bytes)
[2026-03-16T02:30:09.403+0000] {subprocess.py:93} INFO - 26/03/16 02:30:09 INFO Executor: Running task 43.0 in stage 0.0 (TID 43)
[2026-03-16T02:30:09.404+0000] {subprocess.py:93} INFO - 26/03/16 02:30:09 INFO Executor: Finished task 32.0 in stage 0.0 (TID 32). 3075 bytes result sent to driver
[2026-03-16T02:30:09.404+0000] {subprocess.py:93} INFO - 26/03/16 02:30:09 INFO TaskSetManager: Starting task 45.0 in stage 0.0 (TID 45) (c3cb001f81d0, executor driver, partition 45, PROCESS_LOCAL, 8189 bytes)
[2026-03-16T02:30:09.405+0000] {subprocess.py:93} INFO - 26/03/16 02:30:09 INFO Executor: Running task 45.0 in stage 0.0 (TID 45)
[2026-03-16T02:30:09.405+0000] {subprocess.py:93} INFO - 26/03/16 02:30:09 INFO Executor: Finished task 33.0 in stage 0.0 (TID 33). 3078 bytes result sent to driver
[2026-03-16T02:30:09.405+0000] {subprocess.py:93} INFO - 26/03/16 02:30:09 INFO Executor: Running task 44.0 in stage 0.0 (TID 44)
[2026-03-16T02:30:09.410+0000] {subprocess.py:93} INFO - 26/03/16 02:30:09 INFO TaskSetManager: Starting task 46.0 in stage 0.0 (TID 46) (c3cb001f81d0, executor driver, partition 46, PROCESS_LOCAL, 8188 bytes)
[2026-03-16T02:30:09.411+0000] {subprocess.py:93} INFO - 26/03/16 02:30:09 INFO TaskSetManager: Finished task 30.0 in stage 0.0 (TID 30) in 94 ms on c3cb001f81d0 (executor driver) (32/137)
[2026-03-16T02:30:09.414+0000] {subprocess.py:93} INFO - 26/03/16 02:30:09 INFO TaskSetManager: Finished task 34.0 in stage 0.0 (TID 34) in 63 ms on c3cb001f81d0 (executor driver) (33/137)
[2026-03-16T02:30:09.415+0000] {subprocess.py:93} INFO - 26/03/16 02:30:09 INFO Executor: Running task 46.0 in stage 0.0 (TID 46)
[2026-03-16T02:30:09.421+0000] {subprocess.py:93} INFO - 26/03/16 02:30:09 INFO TaskSetManager: Finished task 33.0 in stage 0.0 (TID 33) in 69 ms on c3cb001f81d0 (executor driver) (34/137)
[2026-03-16T02:30:09.422+0000] {subprocess.py:93} INFO - 26/03/16 02:30:09 INFO TaskSetManager: Finished task 32.0 in stage 0.0 (TID 32) in 104 ms on c3cb001f81d0 (executor driver) (35/137)
[2026-03-16T02:30:09.423+0000] {subprocess.py:93} INFO - 26/03/16 02:30:09 INFO Executor: Finished task 39.0 in stage 0.0 (TID 39). 3100 bytes result sent to driver
[2026-03-16T02:30:09.424+0000] {subprocess.py:93} INFO - 26/03/16 02:30:09 INFO TaskSetManager: Starting task 47.0 in stage 0.0 (TID 47) (c3cb001f81d0, executor driver, partition 47, PROCESS_LOCAL, 8187 bytes)
[2026-03-16T02:30:09.425+0000] {subprocess.py:93} INFO - 26/03/16 02:30:09 INFO Executor: Finished task 36.0 in stage 0.0 (TID 36). 3115 bytes result sent to driver
[2026-03-16T02:30:09.425+0000] {subprocess.py:93} INFO - 26/03/16 02:30:09 INFO Executor: Running task 47.0 in stage 0.0 (TID 47)
[2026-03-16T02:30:09.426+0000] {subprocess.py:93} INFO - 26/03/16 02:30:09 INFO TaskSetManager: Finished task 39.0 in stage 0.0 (TID 39) in 105 ms on c3cb001f81d0 (executor driver) (36/137)
[2026-03-16T02:30:09.430+0000] {subprocess.py:93} INFO - 26/03/16 02:30:09 INFO TaskSetManager: Starting task 48.0 in stage 0.0 (TID 48) (c3cb001f81d0, executor driver, partition 48, PROCESS_LOCAL, 8190 bytes)
[2026-03-16T02:30:09.431+0000] {subprocess.py:93} INFO - 26/03/16 02:30:09 INFO Executor: Running task 48.0 in stage 0.0 (TID 48)
[2026-03-16T02:30:09.432+0000] {subprocess.py:93} INFO - 26/03/16 02:30:09 INFO TaskSetManager: Finished task 36.0 in stage 0.0 (TID 36) in 121 ms on c3cb001f81d0 (executor driver) (37/137)
[2026-03-16T02:30:09.504+0000] {subprocess.py:93} INFO - 26/03/16 02:30:09 INFO Executor: Finished task 41.0 in stage 0.0 (TID 41). 2771 bytes result sent to driver
[2026-03-16T02:30:09.505+0000] {subprocess.py:93} INFO - 26/03/16 02:30:09 INFO TaskSetManager: Starting task 49.0 in stage 0.0 (TID 49) (c3cb001f81d0, executor driver, partition 49, PROCESS_LOCAL, 8189 bytes)
[2026-03-16T02:30:09.506+0000] {subprocess.py:93} INFO - 26/03/16 02:30:09 INFO Executor: Running task 49.0 in stage 0.0 (TID 49)
[2026-03-16T02:30:09.508+0000] {subprocess.py:93} INFO - 26/03/16 02:30:09 INFO TaskSetManager: Finished task 41.0 in stage 0.0 (TID 41) in 184 ms on c3cb001f81d0 (executor driver) (38/137)
[2026-03-16T02:30:09.572+0000] {subprocess.py:93} INFO - 26/03/16 02:30:09 INFO Executor: Finished task 47.0 in stage 0.0 (TID 47). 3051 bytes result sent to driver
[2026-03-16T02:30:09.574+0000] {subprocess.py:93} INFO - 26/03/16 02:30:09 INFO Executor: Finished task 40.0 in stage 0.0 (TID 40). 3100 bytes result sent to driver
[2026-03-16T02:30:09.584+0000] {subprocess.py:93} INFO - 26/03/16 02:30:09 INFO TaskSetManager: Starting task 50.0 in stage 0.0 (TID 50) (c3cb001f81d0, executor driver, partition 50, PROCESS_LOCAL, 8189 bytes)
[2026-03-16T02:30:09.587+0000] {subprocess.py:93} INFO - 26/03/16 02:30:09 INFO TaskSetManager: Starting task 51.0 in stage 0.0 (TID 51) (c3cb001f81d0, executor driver, partition 51, PROCESS_LOCAL, 8186 bytes)
[2026-03-16T02:30:09.590+0000] {subprocess.py:93} INFO - 26/03/16 02:30:09 INFO Executor: Running task 51.0 in stage 0.0 (TID 51)
[2026-03-16T02:30:09.592+0000] {subprocess.py:93} INFO - 26/03/16 02:30:09 INFO Executor: Finished task 38.0 in stage 0.0 (TID 38). 3106 bytes result sent to driver
[2026-03-16T02:30:09.598+0000] {subprocess.py:93} INFO - 26/03/16 02:30:09 INFO TaskSetManager: Finished task 47.0 in stage 0.0 (TID 47) in 166 ms on c3cb001f81d0 (executor driver) (39/137)
[2026-03-16T02:30:09.606+0000] {subprocess.py:93} INFO - 26/03/16 02:30:09 INFO Executor: Running task 50.0 in stage 0.0 (TID 50)
[2026-03-16T02:30:09.611+0000] {subprocess.py:93} INFO - 26/03/16 02:30:09 INFO Executor: Finished task 35.0 in stage 0.0 (TID 35). 3100 bytes result sent to driver
[2026-03-16T02:30:09.616+0000] {subprocess.py:93} INFO - 26/03/16 02:30:09 INFO Executor: Finished task 43.0 in stage 0.0 (TID 43). 3124 bytes result sent to driver
[2026-03-16T02:30:09.628+0000] {subprocess.py:93} INFO - 26/03/16 02:30:09 INFO TaskSetManager: Starting task 52.0 in stage 0.0 (TID 52) (c3cb001f81d0, executor driver, partition 52, PROCESS_LOCAL, 8188 bytes)
[2026-03-16T02:30:09.629+0000] {subprocess.py:93} INFO - 26/03/16 02:30:09 INFO Executor: Finished task 48.0 in stage 0.0 (TID 48). 3060 bytes result sent to driver
[2026-03-16T02:30:09.630+0000] {subprocess.py:93} INFO - 26/03/16 02:30:09 INFO Executor: Finished task 46.0 in stage 0.0 (TID 46). 3097 bytes result sent to driver
[2026-03-16T02:30:09.639+0000] {subprocess.py:93} INFO - 26/03/16 02:30:09 INFO Executor: Finished task 42.0 in stage 0.0 (TID 42). 3109 bytes result sent to driver
[2026-03-16T02:30:09.644+0000] {subprocess.py:93} INFO - 26/03/16 02:30:09 INFO Executor: Finished task 44.0 in stage 0.0 (TID 44). 3167 bytes result sent to driver
[2026-03-16T02:30:09.656+0000] {subprocess.py:93} INFO - 26/03/16 02:30:09 INFO Executor: Finished task 45.0 in stage 0.0 (TID 45). 3143 bytes result sent to driver
[2026-03-16T02:30:09.658+0000] {subprocess.py:93} INFO - 26/03/16 02:30:09 INFO TaskSetManager: Starting task 53.0 in stage 0.0 (TID 53) (c3cb001f81d0, executor driver, partition 53, PROCESS_LOCAL, 8193 bytes)
[2026-03-16T02:30:09.661+0000] {subprocess.py:93} INFO - 26/03/16 02:30:09 INFO Executor: Finished task 37.0 in stage 0.0 (TID 37). 3140 bytes result sent to driver
[2026-03-16T02:30:09.666+0000] {subprocess.py:93} INFO - 26/03/16 02:30:09 INFO Executor: Running task 52.0 in stage 0.0 (TID 52)
[2026-03-16T02:30:09.670+0000] {subprocess.py:93} INFO - 26/03/16 02:30:09 INFO TaskSetManager: Finished task 40.0 in stage 0.0 (TID 40) in 267 ms on c3cb001f81d0 (executor driver) (40/137)
[2026-03-16T02:30:09.676+0000] {subprocess.py:93} INFO - 26/03/16 02:30:09 INFO Executor: Running task 53.0 in stage 0.0 (TID 53)
[2026-03-16T02:30:09.679+0000] {subprocess.py:93} INFO - 26/03/16 02:30:09 INFO TaskSetManager: Starting task 54.0 in stage 0.0 (TID 54) (c3cb001f81d0, executor driver, partition 54, PROCESS_LOCAL, 8193 bytes)
[2026-03-16T02:30:09.684+0000] {subprocess.py:93} INFO - 26/03/16 02:30:09 INFO TaskSetManager: Finished task 38.0 in stage 0.0 (TID 38) in 287 ms on c3cb001f81d0 (executor driver) (41/137)
[2026-03-16T02:30:09.686+0000] {subprocess.py:93} INFO - 26/03/16 02:30:09 INFO Executor: Running task 54.0 in stage 0.0 (TID 54)
[2026-03-16T02:30:09.688+0000] {subprocess.py:93} INFO - 26/03/16 02:30:09 INFO TaskSetManager: Starting task 55.0 in stage 0.0 (TID 55) (c3cb001f81d0, executor driver, partition 55, PROCESS_LOCAL, 8188 bytes)
[2026-03-16T02:30:09.694+0000] {subprocess.py:93} INFO - 26/03/16 02:30:09 INFO Executor: Running task 55.0 in stage 0.0 (TID 55)
[2026-03-16T02:30:09.699+0000] {subprocess.py:93} INFO - 26/03/16 02:30:09 INFO TaskSetManager: Starting task 56.0 in stage 0.0 (TID 56) (c3cb001f81d0, executor driver, partition 56, PROCESS_LOCAL, 8190 bytes)
[2026-03-16T02:30:09.700+0000] {subprocess.py:93} INFO - 26/03/16 02:30:09 INFO TaskSetManager: Starting task 57.0 in stage 0.0 (TID 57) (c3cb001f81d0, executor driver, partition 57, PROCESS_LOCAL, 8187 bytes)
[2026-03-16T02:30:09.702+0000] {subprocess.py:93} INFO - 26/03/16 02:30:09 INFO Executor: Running task 56.0 in stage 0.0 (TID 56)
[2026-03-16T02:30:09.705+0000] {subprocess.py:93} INFO - 26/03/16 02:30:09 INFO Executor: Running task 57.0 in stage 0.0 (TID 57)
[2026-03-16T02:30:09.710+0000] {subprocess.py:93} INFO - 26/03/16 02:30:09 INFO TaskSetManager: Starting task 58.0 in stage 0.0 (TID 58) (c3cb001f81d0, executor driver, partition 58, PROCESS_LOCAL, 8189 bytes)
[2026-03-16T02:30:09.711+0000] {subprocess.py:93} INFO - 26/03/16 02:30:09 INFO TaskSetManager: Finished task 46.0 in stage 0.0 (TID 46) in 265 ms on c3cb001f81d0 (executor driver) (42/137)
[2026-03-16T02:30:09.713+0000] {subprocess.py:93} INFO - 26/03/16 02:30:09 INFO TaskSetManager: Finished task 35.0 in stage 0.0 (TID 35) in 315 ms on c3cb001f81d0 (executor driver) (43/137)
[2026-03-16T02:30:09.715+0000] {subprocess.py:93} INFO - 26/03/16 02:30:09 INFO TaskSetManager: Finished task 44.0 in stage 0.0 (TID 44) in 276 ms on c3cb001f81d0 (executor driver) (44/137)
[2026-03-16T02:30:09.716+0000] {subprocess.py:93} INFO - 26/03/16 02:30:09 INFO Executor: Running task 58.0 in stage 0.0 (TID 58)
[2026-03-16T02:30:09.717+0000] {subprocess.py:93} INFO - 26/03/16 02:30:09 INFO TaskSetManager: Finished task 48.0 in stage 0.0 (TID 48) in 195 ms on c3cb001f81d0 (executor driver) (45/137)
[2026-03-16T02:30:09.719+0000] {subprocess.py:93} INFO - 26/03/16 02:30:09 INFO TaskSetManager: Finished task 42.0 in stage 0.0 (TID 42) in 289 ms on c3cb001f81d0 (executor driver) (46/137)
[2026-03-16T02:30:09.722+0000] {subprocess.py:93} INFO - 26/03/16 02:30:09 INFO TaskSetManager: Starting task 59.0 in stage 0.0 (TID 59) (c3cb001f81d0, executor driver, partition 59, PROCESS_LOCAL, 8190 bytes)
[2026-03-16T02:30:09.724+0000] {subprocess.py:93} INFO - 26/03/16 02:30:09 INFO TaskSetManager: Starting task 60.0 in stage 0.0 (TID 60) (c3cb001f81d0, executor driver, partition 60, PROCESS_LOCAL, 8195 bytes)
[2026-03-16T02:30:09.726+0000] {subprocess.py:93} INFO - 26/03/16 02:30:09 INFO TaskSetManager: Finished task 43.0 in stage 0.0 (TID 43) in 293 ms on c3cb001f81d0 (executor driver) (47/137)
[2026-03-16T02:30:09.728+0000] {subprocess.py:93} INFO - 26/03/16 02:30:09 INFO Executor: Running task 59.0 in stage 0.0 (TID 59)
[2026-03-16T02:30:09.736+0000] {subprocess.py:93} INFO - 26/03/16 02:30:09 INFO TaskSetManager: Finished task 37.0 in stage 0.0 (TID 37) in 317 ms on c3cb001f81d0 (executor driver) (48/137)
[2026-03-16T02:30:09.741+0000] {subprocess.py:93} INFO - 26/03/16 02:30:09 INFO TaskSetManager: Finished task 45.0 in stage 0.0 (TID 45) in 282 ms on c3cb001f81d0 (executor driver) (49/137)
[2026-03-16T02:30:09.742+0000] {subprocess.py:93} INFO - 26/03/16 02:30:09 INFO Executor: Finished task 51.0 in stage 0.0 (TID 51). 3048 bytes result sent to driver
[2026-03-16T02:30:09.743+0000] {subprocess.py:93} INFO - 26/03/16 02:30:09 INFO Executor: Finished task 54.0 in stage 0.0 (TID 54). 2736 bytes result sent to driver
[2026-03-16T02:30:09.744+0000] {subprocess.py:93} INFO - 26/03/16 02:30:09 INFO Executor: Finished task 50.0 in stage 0.0 (TID 50). 3057 bytes result sent to driver
[2026-03-16T02:30:09.747+0000] {subprocess.py:93} INFO - 26/03/16 02:30:09 INFO TaskSetManager: Starting task 61.0 in stage 0.0 (TID 61) (c3cb001f81d0, executor driver, partition 61, PROCESS_LOCAL, 8191 bytes)
[2026-03-16T02:30:09.749+0000] {subprocess.py:93} INFO - 26/03/16 02:30:09 INFO Executor: Running task 60.0 in stage 0.0 (TID 60)
[2026-03-16T02:30:09.754+0000] {subprocess.py:93} INFO - 26/03/16 02:30:09 INFO Executor: Running task 61.0 in stage 0.0 (TID 61)
[2026-03-16T02:30:09.755+0000] {subprocess.py:93} INFO - 26/03/16 02:30:09 INFO TaskSetManager: Starting task 62.0 in stage 0.0 (TID 62) (c3cb001f81d0, executor driver, partition 62, PROCESS_LOCAL, 8187 bytes)
[2026-03-16T02:30:09.759+0000] {subprocess.py:93} INFO - 26/03/16 02:30:09 INFO Executor: Running task 62.0 in stage 0.0 (TID 62)
[2026-03-16T02:30:09.760+0000] {subprocess.py:93} INFO - 26/03/16 02:30:09 INFO TaskSetManager: Starting task 63.0 in stage 0.0 (TID 63) (c3cb001f81d0, executor driver, partition 63, PROCESS_LOCAL, 8188 bytes)
[2026-03-16T02:30:09.764+0000] {subprocess.py:93} INFO - 26/03/16 02:30:09 INFO Executor: Finished task 52.0 in stage 0.0 (TID 52). 3054 bytes result sent to driver
[2026-03-16T02:30:09.770+0000] {subprocess.py:93} INFO - 26/03/16 02:30:09 INFO TaskSetManager: Finished task 50.0 in stage 0.0 (TID 50) in 76 ms on c3cb001f81d0 (executor driver) (50/137)
[2026-03-16T02:30:09.772+0000] {subprocess.py:93} INFO - 26/03/16 02:30:09 INFO Executor: Running task 63.0 in stage 0.0 (TID 63)
[2026-03-16T02:30:09.773+0000] {subprocess.py:93} INFO - 26/03/16 02:30:09 INFO TaskSetManager: Finished task 51.0 in stage 0.0 (TID 51) in 80 ms on c3cb001f81d0 (executor driver) (51/137)
[2026-03-16T02:30:09.774+0000] {subprocess.py:93} INFO - 26/03/16 02:30:09 INFO TaskSetManager: Finished task 54.0 in stage 0.0 (TID 54) in 74 ms on c3cb001f81d0 (executor driver) (52/137)
[2026-03-16T02:30:09.777+0000] {subprocess.py:93} INFO - 26/03/16 02:30:09 INFO TaskSetManager: Starting task 64.0 in stage 0.0 (TID 64) (c3cb001f81d0, executor driver, partition 64, PROCESS_LOCAL, 8190 bytes)
[2026-03-16T02:30:09.778+0000] {subprocess.py:93} INFO - 26/03/16 02:30:09 INFO Executor: Running task 64.0 in stage 0.0 (TID 64)
[2026-03-16T02:30:09.783+0000] {subprocess.py:93} INFO - 26/03/16 02:30:09 INFO TaskSetManager: Finished task 52.0 in stage 0.0 (TID 52) in 89 ms on c3cb001f81d0 (executor driver) (53/137)
[2026-03-16T02:30:09.793+0000] {subprocess.py:93} INFO - 26/03/16 02:30:09 INFO Executor: Finished task 49.0 in stage 0.0 (TID 49). 3057 bytes result sent to driver
[2026-03-16T02:30:09.798+0000] {subprocess.py:93} INFO - 26/03/16 02:30:09 INFO Executor: Finished task 56.0 in stage 0.0 (TID 56). 3103 bytes result sent to driver
[2026-03-16T02:30:09.800+0000] {subprocess.py:93} INFO - 26/03/16 02:30:09 INFO Executor: Finished task 60.0 in stage 0.0 (TID 60). 3075 bytes result sent to driver
[2026-03-16T02:30:09.805+0000] {subprocess.py:93} INFO - 26/03/16 02:30:09 INFO TaskSetManager: Starting task 65.0 in stage 0.0 (TID 65) (c3cb001f81d0, executor driver, partition 65, PROCESS_LOCAL, 8189 bytes)
[2026-03-16T02:30:09.809+0000] {subprocess.py:93} INFO - 26/03/16 02:30:09 INFO Executor: Finished task 57.0 in stage 0.0 (TID 57). 3094 bytes result sent to driver
[2026-03-16T02:30:09.809+0000] {subprocess.py:93} INFO - 26/03/16 02:30:09 INFO TaskSetManager: Starting task 66.0 in stage 0.0 (TID 66) (c3cb001f81d0, executor driver, partition 66, PROCESS_LOCAL, 8188 bytes)
[2026-03-16T02:30:09.810+0000] {subprocess.py:93} INFO - 26/03/16 02:30:09 INFO Executor: Running task 65.0 in stage 0.0 (TID 65)
[2026-03-16T02:30:09.812+0000] {subprocess.py:93} INFO - 26/03/16 02:30:09 INFO Executor: Running task 66.0 in stage 0.0 (TID 66)
[2026-03-16T02:30:09.814+0000] {subprocess.py:93} INFO - 26/03/16 02:30:09 INFO Executor: Finished task 55.0 in stage 0.0 (TID 55). 3097 bytes result sent to driver
[2026-03-16T02:30:09.815+0000] {subprocess.py:93} INFO - 26/03/16 02:30:09 INFO Executor: Finished task 62.0 in stage 0.0 (TID 62). 3094 bytes result sent to driver
[2026-03-16T02:30:09.815+0000] {subprocess.py:93} INFO - 26/03/16 02:30:09 INFO TaskSetManager: Starting task 67.0 in stage 0.0 (TID 67) (c3cb001f81d0, executor driver, partition 67, PROCESS_LOCAL, 8190 bytes)
[2026-03-16T02:30:09.816+0000] {subprocess.py:93} INFO - 26/03/16 02:30:09 INFO TaskSetManager: Starting task 68.0 in stage 0.0 (TID 68) (c3cb001f81d0, executor driver, partition 68, PROCESS_LOCAL, 8191 bytes)
[2026-03-16T02:30:09.816+0000] {subprocess.py:93} INFO - 26/03/16 02:30:09 INFO TaskSetManager: Finished task 49.0 in stage 0.0 (TID 49) in 203 ms on c3cb001f81d0 (executor driver) (54/137)
[2026-03-16T02:30:09.818+0000] {subprocess.py:93} INFO - 26/03/16 02:30:09 INFO Executor: Finished task 58.0 in stage 0.0 (TID 58). 3057 bytes result sent to driver
[2026-03-16T02:30:09.821+0000] {subprocess.py:93} INFO - 26/03/16 02:30:09 INFO Executor: Finished task 53.0 in stage 0.0 (TID 53). 3112 bytes result sent to driver
[2026-03-16T02:30:09.825+0000] {subprocess.py:93} INFO - 26/03/16 02:30:09 INFO Executor: Running task 67.0 in stage 0.0 (TID 67)
[2026-03-16T02:30:09.832+0000] {subprocess.py:93} INFO - 26/03/16 02:30:09 INFO Executor: Running task 68.0 in stage 0.0 (TID 68)
[2026-03-16T02:30:09.834+0000] {subprocess.py:93} INFO - 26/03/16 02:30:09 INFO TaskSetManager: Finished task 60.0 in stage 0.0 (TID 60) in 93 ms on c3cb001f81d0 (executor driver) (55/137)
[2026-03-16T02:30:09.838+0000] {subprocess.py:93} INFO - 26/03/16 02:30:09 INFO TaskSetManager: Finished task 56.0 in stage 0.0 (TID 56) in 112 ms on c3cb001f81d0 (executor driver) (56/137)
[2026-03-16T02:30:09.841+0000] {subprocess.py:93} INFO - 26/03/16 02:30:09 INFO Executor: Finished task 61.0 in stage 0.0 (TID 61). 3063 bytes result sent to driver
[2026-03-16T02:30:09.846+0000] {subprocess.py:93} INFO - 26/03/16 02:30:09 INFO TaskSetManager: Finished task 55.0 in stage 0.0 (TID 55) in 118 ms on c3cb001f81d0 (executor driver) (57/137)
[2026-03-16T02:30:09.847+0000] {subprocess.py:93} INFO - 26/03/16 02:30:09 INFO TaskSetManager: Starting task 69.0 in stage 0.0 (TID 69) (c3cb001f81d0, executor driver, partition 69, PROCESS_LOCAL, 8187 bytes)
[2026-03-16T02:30:09.848+0000] {subprocess.py:93} INFO - 26/03/16 02:30:09 INFO TaskSetManager: Starting task 70.0 in stage 0.0 (TID 70) (c3cb001f81d0, executor driver, partition 70, PROCESS_LOCAL, 8190 bytes)
[2026-03-16T02:30:09.850+0000] {subprocess.py:93} INFO - 26/03/16 02:30:09 INFO Executor: Finished task 63.0 in stage 0.0 (TID 63). 2726 bytes result sent to driver
[2026-03-16T02:30:09.851+0000] {subprocess.py:93} INFO - 26/03/16 02:30:09 INFO TaskSetManager: Finished task 62.0 in stage 0.0 (TID 62) in 92 ms on c3cb001f81d0 (executor driver) (58/137)
[2026-03-16T02:30:09.852+0000] {subprocess.py:93} INFO - 26/03/16 02:30:09 INFO Executor: Finished task 59.0 in stage 0.0 (TID 59). 3060 bytes result sent to driver
[2026-03-16T02:30:09.853+0000] {subprocess.py:93} INFO - 26/03/16 02:30:09 INFO Executor: Running task 69.0 in stage 0.0 (TID 69)
[2026-03-16T02:30:09.853+0000] {subprocess.py:93} INFO - 26/03/16 02:30:09 INFO Executor: Running task 70.0 in stage 0.0 (TID 70)
[2026-03-16T02:30:09.854+0000] {subprocess.py:93} INFO - 26/03/16 02:30:09 INFO TaskSetManager: Finished task 53.0 in stage 0.0 (TID 53) in 136 ms on c3cb001f81d0 (executor driver) (59/137)
[2026-03-16T02:30:09.855+0000] {subprocess.py:93} INFO - 26/03/16 02:30:09 INFO TaskSetManager: Finished task 57.0 in stage 0.0 (TID 57) in 123 ms on c3cb001f81d0 (executor driver) (60/137)
[2026-03-16T02:30:09.856+0000] {subprocess.py:93} INFO - 26/03/16 02:30:09 INFO TaskSetManager: Starting task 71.0 in stage 0.0 (TID 71) (c3cb001f81d0, executor driver, partition 71, PROCESS_LOCAL, 8187 bytes)
[2026-03-16T02:30:09.856+0000] {subprocess.py:93} INFO - 26/03/16 02:30:09 INFO TaskSetManager: Starting task 72.0 in stage 0.0 (TID 72) (c3cb001f81d0, executor driver, partition 72, PROCESS_LOCAL, 8190 bytes)
[2026-03-16T02:30:09.857+0000] {subprocess.py:93} INFO - 26/03/16 02:30:09 INFO Executor: Running task 71.0 in stage 0.0 (TID 71)
[2026-03-16T02:30:09.858+0000] {subprocess.py:93} INFO - 26/03/16 02:30:09 INFO Executor: Running task 72.0 in stage 0.0 (TID 72)
[2026-03-16T02:30:09.858+0000] {subprocess.py:93} INFO - 26/03/16 02:30:09 INFO TaskSetManager: Starting task 73.0 in stage 0.0 (TID 73) (c3cb001f81d0, executor driver, partition 73, PROCESS_LOCAL, 8195 bytes)
[2026-03-16T02:30:09.859+0000] {subprocess.py:93} INFO - 26/03/16 02:30:09 INFO Executor: Finished task 64.0 in stage 0.0 (TID 64). 3060 bytes result sent to driver
[2026-03-16T02:30:09.860+0000] {subprocess.py:93} INFO - 26/03/16 02:30:09 INFO Executor: Running task 73.0 in stage 0.0 (TID 73)
[2026-03-16T02:30:09.860+0000] {subprocess.py:93} INFO - 26/03/16 02:30:09 INFO TaskSetManager: Starting task 74.0 in stage 0.0 (TID 74) (c3cb001f81d0, executor driver, partition 74, PROCESS_LOCAL, 8186 bytes)
[2026-03-16T02:30:09.861+0000] {subprocess.py:93} INFO - 26/03/16 02:30:09 INFO TaskSetManager: Starting task 75.0 in stage 0.0 (TID 75) (c3cb001f81d0, executor driver, partition 75, PROCESS_LOCAL, 8187 bytes)
[2026-03-16T02:30:09.861+0000] {subprocess.py:93} INFO - 26/03/16 02:30:09 INFO Executor: Finished task 68.0 in stage 0.0 (TID 68). 3063 bytes result sent to driver
[2026-03-16T02:30:09.862+0000] {subprocess.py:93} INFO - 26/03/16 02:30:09 INFO Executor: Finished task 65.0 in stage 0.0 (TID 65). 2728 bytes result sent to driver
[2026-03-16T02:30:09.862+0000] {subprocess.py:93} INFO - 26/03/16 02:30:09 INFO Executor: Running task 75.0 in stage 0.0 (TID 75)
[2026-03-16T02:30:09.862+0000] {subprocess.py:93} INFO - 26/03/16 02:30:09 INFO Executor: Running task 74.0 in stage 0.0 (TID 74)
[2026-03-16T02:30:09.863+0000] {subprocess.py:93} INFO - 26/03/16 02:30:09 INFO TaskSetManager: Starting task 76.0 in stage 0.0 (TID 76) (c3cb001f81d0, executor driver, partition 76, PROCESS_LOCAL, 8190 bytes)
[2026-03-16T02:30:09.863+0000] {subprocess.py:93} INFO - 26/03/16 02:30:09 INFO Executor: Finished task 67.0 in stage 0.0 (TID 67). 2730 bytes result sent to driver
[2026-03-16T02:30:09.863+0000] {subprocess.py:93} INFO - 26/03/16 02:30:09 INFO TaskSetManager: Starting task 77.0 in stage 0.0 (TID 77) (c3cb001f81d0, executor driver, partition 77, PROCESS_LOCAL, 8188 bytes)
[2026-03-16T02:30:09.864+0000] {subprocess.py:93} INFO - 26/03/16 02:30:09 INFO Executor: Finished task 66.0 in stage 0.0 (TID 66). 3054 bytes result sent to driver
[2026-03-16T02:30:09.864+0000] {subprocess.py:93} INFO - 26/03/16 02:30:09 INFO TaskSetManager: Finished task 58.0 in stage 0.0 (TID 58) in 158 ms on c3cb001f81d0 (executor driver) (61/137)
[2026-03-16T02:30:09.865+0000] {subprocess.py:93} INFO - 26/03/16 02:30:09 INFO Executor: Running task 76.0 in stage 0.0 (TID 76)
[2026-03-16T02:30:09.865+0000] {subprocess.py:93} INFO - 26/03/16 02:30:09 INFO TaskSetManager: Finished task 64.0 in stage 0.0 (TID 64) in 96 ms on c3cb001f81d0 (executor driver) (62/137)
[2026-03-16T02:30:09.866+0000] {subprocess.py:93} INFO - 26/03/16 02:30:09 INFO TaskSetManager: Finished task 61.0 in stage 0.0 (TID 61) in 139 ms on c3cb001f81d0 (executor driver) (63/137)
[2026-03-16T02:30:09.866+0000] {subprocess.py:93} INFO - 26/03/16 02:30:09 INFO TaskSetManager: Finished task 68.0 in stage 0.0 (TID 68) in 59 ms on c3cb001f81d0 (executor driver) (64/137)
[2026-03-16T02:30:09.867+0000] {subprocess.py:93} INFO - 26/03/16 02:30:09 INFO Executor: Running task 77.0 in stage 0.0 (TID 77)
[2026-03-16T02:30:09.867+0000] {subprocess.py:93} INFO - 26/03/16 02:30:09 INFO TaskSetManager: Starting task 78.0 in stage 0.0 (TID 78) (c3cb001f81d0, executor driver, partition 78, PROCESS_LOCAL, 8191 bytes)
[2026-03-16T02:30:09.867+0000] {subprocess.py:93} INFO - 26/03/16 02:30:09 INFO Executor: Running task 78.0 in stage 0.0 (TID 78)
[2026-03-16T02:30:09.868+0000] {subprocess.py:93} INFO - 26/03/16 02:30:09 INFO Executor: Finished task 70.0 in stage 0.0 (TID 70). 2730 bytes result sent to driver
[2026-03-16T02:30:09.868+0000] {subprocess.py:93} INFO - 26/03/16 02:30:09 INFO TaskSetManager: Starting task 79.0 in stage 0.0 (TID 79) (c3cb001f81d0, executor driver, partition 79, PROCESS_LOCAL, 8193 bytes)
[2026-03-16T02:30:09.869+0000] {subprocess.py:93} INFO - 26/03/16 02:30:09 INFO TaskSetManager: Finished task 63.0 in stage 0.0 (TID 63) in 149 ms on c3cb001f81d0 (executor driver) (65/137)
[2026-03-16T02:30:09.869+0000] {subprocess.py:93} INFO - 26/03/16 02:30:09 INFO TaskSetManager: Finished task 65.0 in stage 0.0 (TID 65) in 91 ms on c3cb001f81d0 (executor driver) (66/137)
[2026-03-16T02:30:09.870+0000] {subprocess.py:93} INFO - 26/03/16 02:30:09 INFO TaskSetManager: Finished task 59.0 in stage 0.0 (TID 59) in 171 ms on c3cb001f81d0 (executor driver) (67/137)
[2026-03-16T02:30:09.870+0000] {subprocess.py:93} INFO - 26/03/16 02:30:09 INFO TaskSetManager: Finished task 67.0 in stage 0.0 (TID 67) in 83 ms on c3cb001f81d0 (executor driver) (68/137)
[2026-03-16T02:30:09.870+0000] {subprocess.py:93} INFO - 26/03/16 02:30:09 INFO Executor: Running task 79.0 in stage 0.0 (TID 79)
[2026-03-16T02:30:09.871+0000] {subprocess.py:93} INFO - 26/03/16 02:30:09 INFO Executor: Finished task 69.0 in stage 0.0 (TID 69). 2724 bytes result sent to driver
[2026-03-16T02:30:09.871+0000] {subprocess.py:93} INFO - 26/03/16 02:30:09 INFO TaskSetManager: Starting task 80.0 in stage 0.0 (TID 80) (c3cb001f81d0, executor driver, partition 80, PROCESS_LOCAL, 8190 bytes)
[2026-03-16T02:30:09.872+0000] {subprocess.py:93} INFO - 26/03/16 02:30:09 INFO TaskSetManager: Starting task 81.0 in stage 0.0 (TID 81) (c3cb001f81d0, executor driver, partition 81, PROCESS_LOCAL, 8190 bytes)
[2026-03-16T02:30:09.872+0000] {subprocess.py:93} INFO - 26/03/16 02:30:09 INFO Executor: Finished task 72.0 in stage 0.0 (TID 72). 3060 bytes result sent to driver
[2026-03-16T02:30:09.872+0000] {subprocess.py:93} INFO - 26/03/16 02:30:09 INFO Executor: Running task 80.0 in stage 0.0 (TID 80)
[2026-03-16T02:30:09.873+0000] {subprocess.py:93} INFO - 26/03/16 02:30:09 INFO TaskSetManager: Starting task 82.0 in stage 0.0 (TID 82) (c3cb001f81d0, executor driver, partition 82, PROCESS_LOCAL, 8189 bytes)
[2026-03-16T02:30:09.873+0000] {subprocess.py:93} INFO - 26/03/16 02:30:09 INFO TaskSetManager: Starting task 83.0 in stage 0.0 (TID 83) (c3cb001f81d0, executor driver, partition 83, PROCESS_LOCAL, 8192 bytes)
[2026-03-16T02:30:09.874+0000] {subprocess.py:93} INFO - 26/03/16 02:30:09 INFO Executor: Running task 81.0 in stage 0.0 (TID 81)
[2026-03-16T02:30:09.874+0000] {subprocess.py:93} INFO - 26/03/16 02:30:09 INFO Executor: Finished task 71.0 in stage 0.0 (TID 71). 3051 bytes result sent to driver
[2026-03-16T02:30:09.874+0000] {subprocess.py:93} INFO - 26/03/16 02:30:09 INFO Executor: Running task 82.0 in stage 0.0 (TID 82)
[2026-03-16T02:30:09.875+0000] {subprocess.py:93} INFO - 26/03/16 02:30:09 INFO Executor: Running task 83.0 in stage 0.0 (TID 83)
[2026-03-16T02:30:09.875+0000] {subprocess.py:93} INFO - 26/03/16 02:30:09 INFO TaskSetManager: Starting task 84.0 in stage 0.0 (TID 84) (c3cb001f81d0, executor driver, partition 84, PROCESS_LOCAL, 8185 bytes)
[2026-03-16T02:30:09.875+0000] {subprocess.py:93} INFO - 26/03/16 02:30:09 INFO TaskSetManager: Finished task 72.0 in stage 0.0 (TID 72) in 87 ms on c3cb001f81d0 (executor driver) (69/137)
[2026-03-16T02:30:09.876+0000] {subprocess.py:93} INFO - 26/03/16 02:30:09 INFO TaskSetManager: Finished task 70.0 in stage 0.0 (TID 70) in 102 ms on c3cb001f81d0 (executor driver) (70/137)
[2026-03-16T02:30:09.876+0000] {subprocess.py:93} INFO - 26/03/16 02:30:09 INFO TaskSetManager: Finished task 66.0 in stage 0.0 (TID 66) in 123 ms on c3cb001f81d0 (executor driver) (71/137)
[2026-03-16T02:30:09.876+0000] {subprocess.py:93} INFO - 26/03/16 02:30:09 INFO Executor: Finished task 74.0 in stage 0.0 (TID 74). 3091 bytes result sent to driver
[2026-03-16T02:30:09.877+0000] {subprocess.py:93} INFO - 26/03/16 02:30:09 INFO TaskSetManager: Finished task 69.0 in stage 0.0 (TID 69) in 105 ms on c3cb001f81d0 (executor driver) (72/137)
[2026-03-16T02:30:09.877+0000] {subprocess.py:93} INFO - 26/03/16 02:30:09 INFO TaskSetManager: Finished task 71.0 in stage 0.0 (TID 71) in 95 ms on c3cb001f81d0 (executor driver) (73/137)
[2026-03-16T02:30:09.877+0000] {subprocess.py:93} INFO - 26/03/16 02:30:09 INFO TaskSetManager: Starting task 85.0 in stage 0.0 (TID 85) (c3cb001f81d0, executor driver, partition 85, PROCESS_LOCAL, 8184 bytes)
[2026-03-16T02:30:09.878+0000] {subprocess.py:93} INFO - 26/03/16 02:30:09 INFO Executor: Running task 84.0 in stage 0.0 (TID 84)
[2026-03-16T02:30:09.878+0000] {subprocess.py:93} INFO - 26/03/16 02:30:09 INFO Executor: Running task 85.0 in stage 0.0 (TID 85)
[2026-03-16T02:30:09.879+0000] {subprocess.py:93} INFO - 26/03/16 02:30:09 INFO TaskSetManager: Finished task 74.0 in stage 0.0 (TID 74) in 83 ms on c3cb001f81d0 (executor driver) (74/137)
[2026-03-16T02:30:09.928+0000] {subprocess.py:93} INFO - 26/03/16 02:30:09 INFO Executor: Finished task 73.0 in stage 0.0 (TID 73). 3075 bytes result sent to driver
[2026-03-16T02:30:09.934+0000] {subprocess.py:93} INFO - 26/03/16 02:30:09 INFO TaskSetManager: Starting task 86.0 in stage 0.0 (TID 86) (c3cb001f81d0, executor driver, partition 86, PROCESS_LOCAL, 8190 bytes)
[2026-03-16T02:30:09.937+0000] {subprocess.py:93} INFO - 26/03/16 02:30:09 INFO Executor: Running task 86.0 in stage 0.0 (TID 86)
[2026-03-16T02:30:09.942+0000] {subprocess.py:93} INFO - 26/03/16 02:30:09 INFO TaskSetManager: Finished task 73.0 in stage 0.0 (TID 73) in 201 ms on c3cb001f81d0 (executor driver) (75/137)
[2026-03-16T02:30:09.943+0000] {subprocess.py:93} INFO - 26/03/16 02:30:09 INFO Executor: Finished task 75.0 in stage 0.0 (TID 75). 2724 bytes result sent to driver
[2026-03-16T02:30:09.945+0000] {subprocess.py:93} INFO - 26/03/16 02:30:09 INFO Executor: Finished task 77.0 in stage 0.0 (TID 77). 2726 bytes result sent to driver
[2026-03-16T02:30:09.946+0000] {subprocess.py:93} INFO - 26/03/16 02:30:09 INFO TaskSetManager: Starting task 87.0 in stage 0.0 (TID 87) (c3cb001f81d0, executor driver, partition 87, PROCESS_LOCAL, 8188 bytes)
[2026-03-16T02:30:09.947+0000] {subprocess.py:93} INFO - 26/03/16 02:30:09 INFO Executor: Finished task 81.0 in stage 0.0 (TID 81). 2730 bytes result sent to driver
[2026-03-16T02:30:09.951+0000] {subprocess.py:93} INFO - 26/03/16 02:30:09 INFO TaskSetManager: Starting task 88.0 in stage 0.0 (TID 88) (c3cb001f81d0, executor driver, partition 88, PROCESS_LOCAL, 8197 bytes)
[2026-03-16T02:30:09.952+0000] {subprocess.py:93} INFO - 26/03/16 02:30:09 INFO Executor: Finished task 83.0 in stage 0.0 (TID 83). 3066 bytes result sent to driver
[2026-03-16T02:30:09.954+0000] {subprocess.py:93} INFO - 26/03/16 02:30:09 INFO Executor: Finished task 78.0 in stage 0.0 (TID 78). 3106 bytes result sent to driver
[2026-03-16T02:30:09.956+0000] {subprocess.py:93} INFO - 26/03/16 02:30:09 INFO Executor: Running task 87.0 in stage 0.0 (TID 87)
[2026-03-16T02:30:09.962+0000] {subprocess.py:93} INFO - 26/03/16 02:30:09 INFO Executor: Finished task 79.0 in stage 0.0 (TID 79). 3112 bytes result sent to driver
[2026-03-16T02:30:09.965+0000] {subprocess.py:93} INFO - 26/03/16 02:30:09 INFO Executor: Finished task 80.0 in stage 0.0 (TID 80). 3060 bytes result sent to driver
[2026-03-16T02:30:09.967+0000] {subprocess.py:93} INFO - 26/03/16 02:30:09 INFO TaskSetManager: Finished task 75.0 in stage 0.0 (TID 75) in 204 ms on c3cb001f81d0 (executor driver) (76/137)
[2026-03-16T02:30:09.978+0000] {subprocess.py:93} INFO - 26/03/16 02:30:09 INFO Executor: Running task 88.0 in stage 0.0 (TID 88)
[2026-03-16T02:30:09.991+0000] {subprocess.py:93} INFO - 26/03/16 02:30:09 INFO Executor: Finished task 84.0 in stage 0.0 (TID 84). 3045 bytes result sent to driver
[2026-03-16T02:30:09.999+0000] {subprocess.py:93} INFO - 26/03/16 02:30:09 INFO TaskSetManager: Finished task 77.0 in stage 0.0 (TID 77) in 198 ms on c3cb001f81d0 (executor driver) (77/137)
[2026-03-16T02:30:10.001+0000] {subprocess.py:93} INFO - 26/03/16 02:30:09 INFO Executor: Finished task 82.0 in stage 0.0 (TID 82). 3057 bytes result sent to driver
[2026-03-16T02:30:10.017+0000] {subprocess.py:93} INFO - 26/03/16 02:30:09 INFO Executor: Finished task 85.0 in stage 0.0 (TID 85). 3042 bytes result sent to driver
[2026-03-16T02:30:10.020+0000] {subprocess.py:93} INFO - 26/03/16 02:30:09 INFO Executor: Finished task 76.0 in stage 0.0 (TID 76). 3060 bytes result sent to driver
[2026-03-16T02:30:10.026+0000] {subprocess.py:93} INFO - 26/03/16 02:30:09 INFO TaskSetManager: Starting task 89.0 in stage 0.0 (TID 89) (c3cb001f81d0, executor driver, partition 89, PROCESS_LOCAL, 8194 bytes)
[2026-03-16T02:30:10.027+0000] {subprocess.py:93} INFO - 26/03/16 02:30:09 INFO Executor: Running task 89.0 in stage 0.0 (TID 89)
[2026-03-16T02:30:10.028+0000] {subprocess.py:93} INFO - 26/03/16 02:30:09 INFO TaskSetManager: Starting task 90.0 in stage 0.0 (TID 90) (c3cb001f81d0, executor driver, partition 90, PROCESS_LOCAL, 8194 bytes)
[2026-03-16T02:30:10.029+0000] {subprocess.py:93} INFO - 26/03/16 02:30:09 INFO TaskSetManager: Finished task 81.0 in stage 0.0 (TID 81) in 168 ms on c3cb001f81d0 (executor driver) (78/137)
[2026-03-16T02:30:10.029+0000] {subprocess.py:93} INFO - 26/03/16 02:30:09 INFO Executor: Running task 90.0 in stage 0.0 (TID 90)
[2026-03-16T02:30:10.033+0000] {subprocess.py:93} INFO - 26/03/16 02:30:09 INFO TaskSetManager: Finished task 83.0 in stage 0.0 (TID 83) in 163 ms on c3cb001f81d0 (executor driver) (79/137)
[2026-03-16T02:30:10.035+0000] {subprocess.py:93} INFO - 26/03/16 02:30:09 INFO TaskSetManager: Starting task 91.0 in stage 0.0 (TID 91) (c3cb001f81d0, executor driver, partition 91, PROCESS_LOCAL, 8192 bytes)
[2026-03-16T02:30:10.035+0000] {subprocess.py:93} INFO - 26/03/16 02:30:09 INFO Executor: Running task 91.0 in stage 0.0 (TID 91)
[2026-03-16T02:30:10.036+0000] {subprocess.py:93} INFO - 26/03/16 02:30:09 INFO Executor: Finished task 86.0 in stage 0.0 (TID 86). 3060 bytes result sent to driver
[2026-03-16T02:30:10.037+0000] {subprocess.py:93} INFO - 26/03/16 02:30:09 INFO TaskSetManager: Starting task 92.0 in stage 0.0 (TID 92) (c3cb001f81d0, executor driver, partition 92, PROCESS_LOCAL, 8200 bytes)
[2026-03-16T02:30:10.037+0000] {subprocess.py:93} INFO - 26/03/16 02:30:09 INFO Executor: Running task 92.0 in stage 0.0 (TID 92)
[2026-03-16T02:30:10.040+0000] {subprocess.py:93} INFO - 26/03/16 02:30:09 INFO TaskSetManager: Starting task 93.0 in stage 0.0 (TID 93) (c3cb001f81d0, executor driver, partition 93, PROCESS_LOCAL, 8198 bytes)
[2026-03-16T02:30:10.041+0000] {subprocess.py:93} INFO - 26/03/16 02:30:09 INFO Executor: Running task 93.0 in stage 0.0 (TID 93)
[2026-03-16T02:30:10.050+0000] {subprocess.py:93} INFO - 26/03/16 02:30:09 INFO TaskSetManager: Starting task 94.0 in stage 0.0 (TID 94) (c3cb001f81d0, executor driver, partition 94, PROCESS_LOCAL, 8196 bytes)
[2026-03-16T02:30:10.052+0000] {subprocess.py:93} INFO - 26/03/16 02:30:09 INFO TaskSetManager: Finished task 78.0 in stage 0.0 (TID 78) in 201 ms on c3cb001f81d0 (executor driver) (80/137)
[2026-03-16T02:30:10.054+0000] {subprocess.py:93} INFO - 26/03/16 02:30:09 INFO Executor: Running task 94.0 in stage 0.0 (TID 94)
[2026-03-16T02:30:10.059+0000] {subprocess.py:93} INFO - 26/03/16 02:30:09 INFO TaskSetManager: Starting task 95.0 in stage 0.0 (TID 95) (c3cb001f81d0, executor driver, partition 95, PROCESS_LOCAL, 8194 bytes)
[2026-03-16T02:30:10.062+0000] {subprocess.py:93} INFO - 26/03/16 02:30:09 INFO Executor: Running task 95.0 in stage 0.0 (TID 95)
[2026-03-16T02:30:10.065+0000] {subprocess.py:93} INFO - 26/03/16 02:30:09 INFO TaskSetManager: Starting task 96.0 in stage 0.0 (TID 96) (c3cb001f81d0, executor driver, partition 96, PROCESS_LOCAL, 8197 bytes)
[2026-03-16T02:30:10.067+0000] {subprocess.py:93} INFO - 26/03/16 02:30:09 INFO TaskSetManager: Starting task 97.0 in stage 0.0 (TID 97) (c3cb001f81d0, executor driver, partition 97, PROCESS_LOCAL, 8188 bytes)
[2026-03-16T02:30:10.074+0000] {subprocess.py:93} INFO - 26/03/16 02:30:09 INFO Executor: Finished task 87.0 in stage 0.0 (TID 87). 3054 bytes result sent to driver
[2026-03-16T02:30:10.075+0000] {subprocess.py:93} INFO - 26/03/16 02:30:09 INFO TaskSetManager: Finished task 80.0 in stage 0.0 (TID 80) in 202 ms on c3cb001f81d0 (executor driver) (81/137)
[2026-03-16T02:30:10.078+0000] {subprocess.py:93} INFO - 26/03/16 02:30:09 INFO Executor: Running task 96.0 in stage 0.0 (TID 96)
[2026-03-16T02:30:10.080+0000] {subprocess.py:93} INFO - 26/03/16 02:30:09 INFO Executor: Running task 97.0 in stage 0.0 (TID 97)
[2026-03-16T02:30:10.081+0000] {subprocess.py:93} INFO - 26/03/16 02:30:10 INFO TaskSetManager: Finished task 84.0 in stage 0.0 (TID 84) in 191 ms on c3cb001f81d0 (executor driver) (82/137)
[2026-03-16T02:30:10.082+0000] {subprocess.py:93} INFO - 26/03/16 02:30:10 INFO TaskSetManager: Starting task 98.0 in stage 0.0 (TID 98) (c3cb001f81d0, executor driver, partition 98, PROCESS_LOCAL, 8186 bytes)
[2026-03-16T02:30:10.085+0000] {subprocess.py:93} INFO - 26/03/16 02:30:10 INFO Executor: Running task 98.0 in stage 0.0 (TID 98)
[2026-03-16T02:30:10.088+0000] {subprocess.py:93} INFO - 26/03/16 02:30:10 INFO TaskSetManager: Starting task 99.0 in stage 0.0 (TID 99) (c3cb001f81d0, executor driver, partition 99, PROCESS_LOCAL, 8190 bytes)
[2026-03-16T02:30:10.089+0000] {subprocess.py:93} INFO - 26/03/16 02:30:10 INFO TaskSetManager: Finished task 82.0 in stage 0.0 (TID 82) in 215 ms on c3cb001f81d0 (executor driver) (83/137)
[2026-03-16T02:30:10.093+0000] {subprocess.py:93} INFO - 26/03/16 02:30:10 INFO Executor: Finished task 88.0 in stage 0.0 (TID 88). 3124 bytes result sent to driver
[2026-03-16T02:30:10.094+0000] {subprocess.py:93} INFO - 26/03/16 02:30:10 INFO TaskSetManager: Finished task 86.0 in stage 0.0 (TID 86) in 78 ms on c3cb001f81d0 (executor driver) (84/137)
[2026-03-16T02:30:10.096+0000] {subprocess.py:93} INFO - 26/03/16 02:30:10 INFO TaskSetManager: Finished task 79.0 in stage 0.0 (TID 79) in 240 ms on c3cb001f81d0 (executor driver) (85/137)
[2026-03-16T02:30:10.098+0000] {subprocess.py:93} INFO - 26/03/16 02:30:10 INFO TaskSetManager: Finished task 85.0 in stage 0.0 (TID 85) in 209 ms on c3cb001f81d0 (executor driver) (86/137)
[2026-03-16T02:30:10.100+0000] {subprocess.py:93} INFO - 26/03/16 02:30:10 INFO Executor: Finished task 92.0 in stage 0.0 (TID 92). 2750 bytes result sent to driver
[2026-03-16T02:30:10.102+0000] {subprocess.py:93} INFO - 26/03/16 02:30:10 INFO TaskSetManager: Finished task 76.0 in stage 0.0 (TID 76) in 277 ms on c3cb001f81d0 (executor driver) (87/137)
[2026-03-16T02:30:10.105+0000] {subprocess.py:93} INFO - 26/03/16 02:30:10 INFO TaskSetManager: Finished task 87.0 in stage 0.0 (TID 87) in 94 ms on c3cb001f81d0 (executor driver) (88/137)
[2026-03-16T02:30:10.107+0000] {subprocess.py:93} INFO - 26/03/16 02:30:10 INFO TaskSetManager: Starting task 100.0 in stage 0.0 (TID 100) (c3cb001f81d0, executor driver, partition 100, PROCESS_LOCAL, 8188 bytes)
[2026-03-16T02:30:10.108+0000] {subprocess.py:93} INFO - 26/03/16 02:30:10 INFO Executor: Running task 99.0 in stage 0.0 (TID 99)
[2026-03-16T02:30:10.109+0000] {subprocess.py:93} INFO - 26/03/16 02:30:10 INFO Executor: Running task 100.0 in stage 0.0 (TID 100)
[2026-03-16T02:30:10.119+0000] {subprocess.py:93} INFO - 26/03/16 02:30:10 INFO Executor: Finished task 93.0 in stage 0.0 (TID 93). 3127 bytes result sent to driver
[2026-03-16T02:30:10.120+0000] {subprocess.py:93} INFO - 26/03/16 02:30:10 INFO TaskSetManager: Starting task 101.0 in stage 0.0 (TID 101) (c3cb001f81d0, executor driver, partition 101, PROCESS_LOCAL, 8187 bytes)
[2026-03-16T02:30:10.126+0000] {subprocess.py:93} INFO - 26/03/16 02:30:10 INFO Executor: Finished task 89.0 in stage 0.0 (TID 89). 3115 bytes result sent to driver
[2026-03-16T02:30:10.129+0000] {subprocess.py:93} INFO - 26/03/16 02:30:10 INFO Executor: Running task 101.0 in stage 0.0 (TID 101)
[2026-03-16T02:30:10.132+0000] {subprocess.py:93} INFO - 26/03/16 02:30:10 INFO Executor: Finished task 91.0 in stage 0.0 (TID 91). 3152 bytes result sent to driver
[2026-03-16T02:30:10.135+0000] {subprocess.py:93} INFO - 26/03/16 02:30:10 INFO TaskSetManager: Starting task 102.0 in stage 0.0 (TID 102) (c3cb001f81d0, executor driver, partition 102, PROCESS_LOCAL, 8194 bytes)
[2026-03-16T02:30:10.137+0000] {subprocess.py:93} INFO - 26/03/16 02:30:10 INFO TaskSetManager: Finished task 88.0 in stage 0.0 (TID 88) in 111 ms on c3cb001f81d0 (executor driver) (89/137)
[2026-03-16T02:30:10.139+0000] {subprocess.py:93} INFO - 26/03/16 02:30:10 INFO Executor: Running task 102.0 in stage 0.0 (TID 102)
[2026-03-16T02:30:10.140+0000] {subprocess.py:93} INFO - 26/03/16 02:30:10 INFO TaskSetManager: Starting task 103.0 in stage 0.0 (TID 103) (c3cb001f81d0, executor driver, partition 103, PROCESS_LOCAL, 8192 bytes)
[2026-03-16T02:30:10.142+0000] {subprocess.py:93} INFO - 26/03/16 02:30:10 INFO TaskSetManager: Finished task 93.0 in stage 0.0 (TID 93) in 94 ms on c3cb001f81d0 (executor driver) (90/137)
[2026-03-16T02:30:10.144+0000] {subprocess.py:93} INFO - 26/03/16 02:30:10 INFO Executor: Running task 103.0 in stage 0.0 (TID 103)
[2026-03-16T02:30:10.147+0000] {subprocess.py:93} INFO - 26/03/16 02:30:10 INFO TaskSetManager: Starting task 104.0 in stage 0.0 (TID 104) (c3cb001f81d0, executor driver, partition 104, PROCESS_LOCAL, 8187 bytes)
[2026-03-16T02:30:10.151+0000] {subprocess.py:93} INFO - 26/03/16 02:30:10 INFO TaskSetManager: Finished task 92.0 in stage 0.0 (TID 92) in 101 ms on c3cb001f81d0 (executor driver) (91/137)
[2026-03-16T02:30:10.153+0000] {subprocess.py:93} INFO - 26/03/16 02:30:10 INFO TaskSetManager: Finished task 89.0 in stage 0.0 (TID 89) in 108 ms on c3cb001f81d0 (executor driver) (92/137)
[2026-03-16T02:30:10.157+0000] {subprocess.py:93} INFO - 26/03/16 02:30:10 INFO TaskSetManager: Finished task 91.0 in stage 0.0 (TID 91) in 105 ms on c3cb001f81d0 (executor driver) (93/137)
[2026-03-16T02:30:10.158+0000] {subprocess.py:93} INFO - 26/03/16 02:30:10 INFO Executor: Running task 104.0 in stage 0.0 (TID 104)
[2026-03-16T02:30:10.160+0000] {subprocess.py:93} INFO - 26/03/16 02:30:10 INFO Executor: Finished task 97.0 in stage 0.0 (TID 97). 3097 bytes result sent to driver
[2026-03-16T02:30:10.161+0000] {subprocess.py:93} INFO - 26/03/16 02:30:10 INFO Executor: Finished task 96.0 in stage 0.0 (TID 96). 2787 bytes result sent to driver
[2026-03-16T02:30:10.163+0000] {subprocess.py:93} INFO - 26/03/16 02:30:10 INFO TaskSetManager: Starting task 105.0 in stage 0.0 (TID 105) (c3cb001f81d0, executor driver, partition 105, PROCESS_LOCAL, 8185 bytes)
[2026-03-16T02:30:10.166+0000] {subprocess.py:93} INFO - 26/03/16 02:30:10 INFO TaskSetManager: Starting task 106.0 in stage 0.0 (TID 106) (c3cb001f81d0, executor driver, partition 106, PROCESS_LOCAL, 8196 bytes)
[2026-03-16T02:30:10.167+0000] {subprocess.py:93} INFO - 26/03/16 02:30:10 INFO Executor: Running task 106.0 in stage 0.0 (TID 106)
[2026-03-16T02:30:10.168+0000] {subprocess.py:93} INFO - 26/03/16 02:30:10 INFO Executor: Finished task 102.0 in stage 0.0 (TID 102). 3072 bytes result sent to driver
[2026-03-16T02:30:10.170+0000] {subprocess.py:93} INFO - 26/03/16 02:30:10 INFO TaskSetManager: Finished task 97.0 in stage 0.0 (TID 97) in 104 ms on c3cb001f81d0 (executor driver) (94/137)
[2026-03-16T02:30:10.171+0000] {subprocess.py:93} INFO - 26/03/16 02:30:10 INFO Executor: Finished task 94.0 in stage 0.0 (TID 94). 3121 bytes result sent to driver
[2026-03-16T02:30:10.172+0000] {subprocess.py:93} INFO - 26/03/16 02:30:10 INFO Executor: Finished task 90.0 in stage 0.0 (TID 90). 3158 bytes result sent to driver
[2026-03-16T02:30:10.175+0000] {subprocess.py:93} INFO - 26/03/16 02:30:10 INFO Executor: Running task 105.0 in stage 0.0 (TID 105)
[2026-03-16T02:30:10.178+0000] {subprocess.py:93} INFO - 26/03/16 02:30:10 INFO TaskSetManager: Finished task 96.0 in stage 0.0 (TID 96) in 117 ms on c3cb001f81d0 (executor driver) (95/137)
[2026-03-16T02:30:10.179+0000] {subprocess.py:93} INFO - 26/03/16 02:30:10 INFO TaskSetManager: Starting task 107.0 in stage 0.0 (TID 107) (c3cb001f81d0, executor driver, partition 107, PROCESS_LOCAL, 8191 bytes)
[2026-03-16T02:30:10.182+0000] {subprocess.py:93} INFO - 26/03/16 02:30:10 INFO Executor: Finished task 98.0 in stage 0.0 (TID 98). 3134 bytes result sent to driver
[2026-03-16T02:30:10.184+0000] {subprocess.py:93} INFO - 26/03/16 02:30:10 INFO TaskSetManager: Starting task 108.0 in stage 0.0 (TID 108) (c3cb001f81d0, executor driver, partition 108, PROCESS_LOCAL, 8184 bytes)
[2026-03-16T02:30:10.185+0000] {subprocess.py:93} INFO - 26/03/16 02:30:10 INFO Executor: Finished task 99.0 in stage 0.0 (TID 99). 3103 bytes result sent to driver
[2026-03-16T02:30:10.187+0000] {subprocess.py:93} INFO - 26/03/16 02:30:10 INFO Executor: Finished task 95.0 in stage 0.0 (TID 95). 3115 bytes result sent to driver
[2026-03-16T02:30:10.188+0000] {subprocess.py:93} INFO - 26/03/16 02:30:10 INFO Executor: Running task 108.0 in stage 0.0 (TID 108)
[2026-03-16T02:30:10.189+0000] {subprocess.py:93} INFO - 26/03/16 02:30:10 INFO Executor: Running task 107.0 in stage 0.0 (TID 107)
[2026-03-16T02:30:10.191+0000] {subprocess.py:93} INFO - 26/03/16 02:30:10 INFO Executor: Finished task 100.0 in stage 0.0 (TID 100). 3097 bytes result sent to driver
[2026-03-16T02:30:10.192+0000] {subprocess.py:93} INFO - 26/03/16 02:30:10 INFO TaskSetManager: Starting task 109.0 in stage 0.0 (TID 109) (c3cb001f81d0, executor driver, partition 109, PROCESS_LOCAL, 8190 bytes)
[2026-03-16T02:30:10.195+0000] {subprocess.py:93} INFO - 26/03/16 02:30:10 INFO TaskSetManager: Starting task 110.0 in stage 0.0 (TID 110) (c3cb001f81d0, executor driver, partition 110, PROCESS_LOCAL, 8187 bytes)
[2026-03-16T02:30:10.198+0000] {subprocess.py:93} INFO - 26/03/16 02:30:10 INFO Executor: Running task 109.0 in stage 0.0 (TID 109)
[2026-03-16T02:30:10.201+0000] {subprocess.py:93} INFO - 26/03/16 02:30:10 INFO TaskSetManager: Finished task 94.0 in stage 0.0 (TID 94) in 141 ms on c3cb001f81d0 (executor driver) (96/137)
[2026-03-16T02:30:10.202+0000] {subprocess.py:93} INFO - 26/03/16 02:30:10 INFO TaskSetManager: Finished task 98.0 in stage 0.0 (TID 98) in 107 ms on c3cb001f81d0 (executor driver) (97/137)
[2026-03-16T02:30:10.205+0000] {subprocess.py:93} INFO - 26/03/16 02:30:10 INFO TaskSetManager: Finished task 102.0 in stage 0.0 (TID 102) in 58 ms on c3cb001f81d0 (executor driver) (98/137)
[2026-03-16T02:30:10.207+0000] {subprocess.py:93} INFO - 26/03/16 02:30:10 INFO Executor: Running task 110.0 in stage 0.0 (TID 110)
[2026-03-16T02:30:10.214+0000] {subprocess.py:93} INFO - 26/03/16 02:30:10 INFO TaskSetManager: Starting task 111.0 in stage 0.0 (TID 111) (c3cb001f81d0, executor driver, partition 111, PROCESS_LOCAL, 8191 bytes)
[2026-03-16T02:30:10.215+0000] {subprocess.py:93} INFO - 26/03/16 02:30:10 INFO Executor: Running task 111.0 in stage 0.0 (TID 111)
[2026-03-16T02:30:10.217+0000] {subprocess.py:93} INFO - 26/03/16 02:30:10 INFO TaskSetManager: Starting task 112.0 in stage 0.0 (TID 112) (c3cb001f81d0, executor driver, partition 112, PROCESS_LOCAL, 8187 bytes)
[2026-03-16T02:30:10.219+0000] {subprocess.py:93} INFO - 26/03/16 02:30:10 INFO TaskSetManager: Starting task 113.0 in stage 0.0 (TID 113) (c3cb001f81d0, executor driver, partition 113, PROCESS_LOCAL, 8198 bytes)
[2026-03-16T02:30:10.221+0000] {subprocess.py:93} INFO - 26/03/16 02:30:10 INFO TaskSetManager: Finished task 90.0 in stage 0.0 (TID 90) in 158 ms on c3cb001f81d0 (executor driver) (99/137)
[2026-03-16T02:30:10.223+0000] {subprocess.py:93} INFO - 26/03/16 02:30:10 INFO Executor: Running task 112.0 in stage 0.0 (TID 112)
[2026-03-16T02:30:10.224+0000] {subprocess.py:93} INFO - 26/03/16 02:30:10 INFO Executor: Running task 113.0 in stage 0.0 (TID 113)
[2026-03-16T02:30:10.228+0000] {subprocess.py:93} INFO - 26/03/16 02:30:10 INFO TaskSetManager: Finished task 100.0 in stage 0.0 (TID 100) in 86 ms on c3cb001f81d0 (executor driver) (100/137)
[2026-03-16T02:30:10.230+0000] {subprocess.py:93} INFO - 26/03/16 02:30:10 INFO TaskSetManager: Finished task 99.0 in stage 0.0 (TID 99) in 112 ms on c3cb001f81d0 (executor driver) (101/137)
[2026-03-16T02:30:10.231+0000] {subprocess.py:93} INFO - 26/03/16 02:30:10 INFO TaskSetManager: Finished task 95.0 in stage 0.0 (TID 95) in 142 ms on c3cb001f81d0 (executor driver) (102/137)
[2026-03-16T02:30:10.232+0000] {subprocess.py:93} INFO - 26/03/16 02:30:10 INFO Executor: Finished task 103.0 in stage 0.0 (TID 103). 2734 bytes result sent to driver
[2026-03-16T02:30:10.233+0000] {subprocess.py:93} INFO - 26/03/16 02:30:10 INFO TaskSetManager: Starting task 114.0 in stage 0.0 (TID 114) (c3cb001f81d0, executor driver, partition 114, PROCESS_LOCAL, 8196 bytes)
[2026-03-16T02:30:10.234+0000] {subprocess.py:93} INFO - 26/03/16 02:30:10 INFO Executor: Running task 114.0 in stage 0.0 (TID 114)
[2026-03-16T02:30:10.235+0000] {subprocess.py:93} INFO - 26/03/16 02:30:10 INFO TaskSetManager: Finished task 103.0 in stage 0.0 (TID 103) in 68 ms on c3cb001f81d0 (executor driver) (103/137)
[2026-03-16T02:30:10.236+0000] {subprocess.py:93} INFO - 26/03/16 02:30:10 INFO Executor: Finished task 101.0 in stage 0.0 (TID 101). 3051 bytes result sent to driver
[2026-03-16T02:30:10.236+0000] {subprocess.py:93} INFO - 26/03/16 02:30:10 INFO Executor: Finished task 106.0 in stage 0.0 (TID 106). 3078 bytes result sent to driver
[2026-03-16T02:30:10.237+0000] {subprocess.py:93} INFO - 26/03/16 02:30:10 INFO TaskSetManager: Finished task 101.0 in stage 0.0 (TID 101) in 104 ms on c3cb001f81d0 (executor driver) (104/137)
[2026-03-16T02:30:10.238+0000] {subprocess.py:93} INFO - 26/03/16 02:30:10 INFO Executor: Finished task 104.0 in stage 0.0 (TID 104). 2724 bytes result sent to driver
[2026-03-16T02:30:10.239+0000] {subprocess.py:93} INFO - 26/03/16 02:30:10 INFO TaskSetManager: Starting task 115.0 in stage 0.0 (TID 115) (c3cb001f81d0, executor driver, partition 115, PROCESS_LOCAL, 8192 bytes)
[2026-03-16T02:30:10.239+0000] {subprocess.py:93} INFO - 26/03/16 02:30:10 INFO Executor: Finished task 107.0 in stage 0.0 (TID 107). 2732 bytes result sent to driver
[2026-03-16T02:30:10.240+0000] {subprocess.py:93} INFO - 26/03/16 02:30:10 INFO Executor: Running task 115.0 in stage 0.0 (TID 115)
[2026-03-16T02:30:10.241+0000] {subprocess.py:93} INFO - 26/03/16 02:30:10 INFO Executor: Finished task 105.0 in stage 0.0 (TID 105). 3045 bytes result sent to driver
[2026-03-16T02:30:10.242+0000] {subprocess.py:93} INFO - 26/03/16 02:30:10 INFO TaskSetManager: Starting task 116.0 in stage 0.0 (TID 116) (c3cb001f81d0, executor driver, partition 116, PROCESS_LOCAL, 8185 bytes)
[2026-03-16T02:30:10.242+0000] {subprocess.py:93} INFO - 26/03/16 02:30:10 INFO Executor: Finished task 108.0 in stage 0.0 (TID 108). 3042 bytes result sent to driver
[2026-03-16T02:30:10.243+0000] {subprocess.py:93} INFO - 26/03/16 02:30:10 INFO Executor: Running task 116.0 in stage 0.0 (TID 116)
[2026-03-16T02:30:10.244+0000] {subprocess.py:93} INFO - 26/03/16 02:30:10 INFO TaskSetManager: Starting task 117.0 in stage 0.0 (TID 117) (c3cb001f81d0, executor driver, partition 117, PROCESS_LOCAL, 8191 bytes)
[2026-03-16T02:30:10.245+0000] {subprocess.py:93} INFO - 26/03/16 02:30:10 INFO Executor: Finished task 112.0 in stage 0.0 (TID 112). 3051 bytes result sent to driver
[2026-03-16T02:30:10.245+0000] {subprocess.py:93} INFO - 26/03/16 02:30:10 INFO Executor: Finished task 114.0 in stage 0.0 (TID 114). 3078 bytes result sent to driver
[2026-03-16T02:30:10.246+0000] {subprocess.py:93} INFO - 26/03/16 02:30:10 INFO Executor: Finished task 113.0 in stage 0.0 (TID 113). 3084 bytes result sent to driver
[2026-03-16T02:30:10.247+0000] {subprocess.py:93} INFO - 26/03/16 02:30:10 INFO TaskSetManager: Finished task 106.0 in stage 0.0 (TID 106) in 59 ms on c3cb001f81d0 (executor driver) (105/137)
[2026-03-16T02:30:10.248+0000] {subprocess.py:93} INFO - 26/03/16 02:30:10 INFO Executor: Running task 117.0 in stage 0.0 (TID 117)
[2026-03-16T02:30:10.248+0000] {subprocess.py:93} INFO - 26/03/16 02:30:10 INFO TaskSetManager: Finished task 104.0 in stage 0.0 (TID 104) in 85 ms on c3cb001f81d0 (executor driver) (106/137)
[2026-03-16T02:30:10.249+0000] {subprocess.py:93} INFO - 26/03/16 02:30:10 INFO TaskSetManager: Starting task 118.0 in stage 0.0 (TID 118) (c3cb001f81d0, executor driver, partition 118, PROCESS_LOCAL, 8187 bytes)
[2026-03-16T02:30:10.250+0000] {subprocess.py:93} INFO - 26/03/16 02:30:10 INFO TaskSetManager: Starting task 119.0 in stage 0.0 (TID 119) (c3cb001f81d0, executor driver, partition 119, PROCESS_LOCAL, 8191 bytes)
[2026-03-16T02:30:10.250+0000] {subprocess.py:93} INFO - 26/03/16 02:30:10 INFO Executor: Finished task 109.0 in stage 0.0 (TID 109). 2730 bytes result sent to driver
[2026-03-16T02:30:10.251+0000] {subprocess.py:93} INFO - 26/03/16 02:30:10 INFO Executor: Running task 119.0 in stage 0.0 (TID 119)
[2026-03-16T02:30:10.252+0000] {subprocess.py:93} INFO - 26/03/16 02:30:10 INFO Executor: Running task 118.0 in stage 0.0 (TID 118)
[2026-03-16T02:30:10.252+0000] {subprocess.py:93} INFO - 26/03/16 02:30:10 INFO Executor: Finished task 110.0 in stage 0.0 (TID 110). 3051 bytes result sent to driver
[2026-03-16T02:30:10.253+0000] {subprocess.py:93} INFO - 26/03/16 02:30:10 INFO Executor: Finished task 111.0 in stage 0.0 (TID 111). 3063 bytes result sent to driver
[2026-03-16T02:30:10.254+0000] {subprocess.py:93} INFO - 26/03/16 02:30:10 INFO TaskSetManager: Starting task 120.0 in stage 0.0 (TID 120) (c3cb001f81d0, executor driver, partition 120, PROCESS_LOCAL, 8186 bytes)
[2026-03-16T02:30:10.254+0000] {subprocess.py:93} INFO - 26/03/16 02:30:10 INFO Executor: Running task 120.0 in stage 0.0 (TID 120)
[2026-03-16T02:30:10.255+0000] {subprocess.py:93} INFO - 26/03/16 02:30:10 INFO TaskSetManager: Starting task 121.0 in stage 0.0 (TID 121) (c3cb001f81d0, executor driver, partition 121, PROCESS_LOCAL, 8185 bytes)
[2026-03-16T02:30:10.255+0000] {subprocess.py:93} INFO - 26/03/16 02:30:10 INFO TaskSetManager: Starting task 122.0 in stage 0.0 (TID 122) (c3cb001f81d0, executor driver, partition 122, PROCESS_LOCAL, 8189 bytes)
[2026-03-16T02:30:10.256+0000] {subprocess.py:93} INFO - 26/03/16 02:30:10 INFO Executor: Running task 121.0 in stage 0.0 (TID 121)
[2026-03-16T02:30:10.257+0000] {subprocess.py:93} INFO - 26/03/16 02:30:10 INFO Executor: Running task 122.0 in stage 0.0 (TID 122)
[2026-03-16T02:30:10.257+0000] {subprocess.py:93} INFO - 26/03/16 02:30:10 INFO TaskSetManager: Starting task 123.0 in stage 0.0 (TID 123) (c3cb001f81d0, executor driver, partition 123, PROCESS_LOCAL, 8190 bytes)
[2026-03-16T02:30:10.258+0000] {subprocess.py:93} INFO - 26/03/16 02:30:10 INFO Executor: Finished task 116.0 in stage 0.0 (TID 116). 3045 bytes result sent to driver
[2026-03-16T02:30:10.259+0000] {subprocess.py:93} INFO - 26/03/16 02:30:10 INFO Executor: Running task 123.0 in stage 0.0 (TID 123)
[2026-03-16T02:30:10.259+0000] {subprocess.py:93} INFO - 26/03/16 02:30:10 INFO TaskSetManager: Starting task 124.0 in stage 0.0 (TID 124) (c3cb001f81d0, executor driver, partition 124, PROCESS_LOCAL, 8184 bytes)
[2026-03-16T02:30:10.260+0000] {subprocess.py:93} INFO - 26/03/16 02:30:10 INFO Executor: Finished task 115.0 in stage 0.0 (TID 115). 3066 bytes result sent to driver
[2026-03-16T02:30:10.261+0000] {subprocess.py:93} INFO - 26/03/16 02:30:10 INFO TaskSetManager: Starting task 125.0 in stage 0.0 (TID 125) (c3cb001f81d0, executor driver, partition 125, PROCESS_LOCAL, 8192 bytes)
[2026-03-16T02:30:10.261+0000] {subprocess.py:93} INFO - 26/03/16 02:30:10 INFO Executor: Running task 125.0 in stage 0.0 (TID 125)
[2026-03-16T02:30:10.262+0000] {subprocess.py:93} INFO - 26/03/16 02:30:10 INFO TaskSetManager: Starting task 126.0 in stage 0.0 (TID 126) (c3cb001f81d0, executor driver, partition 126, PROCESS_LOCAL, 8191 bytes)
[2026-03-16T02:30:10.263+0000] {subprocess.py:93} INFO - 26/03/16 02:30:10 INFO Executor: Running task 124.0 in stage 0.0 (TID 124)
[2026-03-16T02:30:10.264+0000] {subprocess.py:93} INFO - 26/03/16 02:30:10 INFO Executor: Finished task 119.0 in stage 0.0 (TID 119). 3063 bytes result sent to driver
[2026-03-16T02:30:10.264+0000] {subprocess.py:93} INFO - 26/03/16 02:30:10 INFO Executor: Finished task 117.0 in stage 0.0 (TID 117). 3063 bytes result sent to driver
[2026-03-16T02:30:10.265+0000] {subprocess.py:93} INFO - 26/03/16 02:30:10 INFO TaskSetManager: Starting task 127.0 in stage 0.0 (TID 127) (c3cb001f81d0, executor driver, partition 127, PROCESS_LOCAL, 8203 bytes)
[2026-03-16T02:30:10.268+0000] {subprocess.py:93} INFO - 26/03/16 02:30:10 INFO Executor: Running task 126.0 in stage 0.0 (TID 126)
[2026-03-16T02:30:10.272+0000] {subprocess.py:93} INFO - 26/03/16 02:30:10 INFO TaskSetManager: Finished task 105.0 in stage 0.0 (TID 105) in 95 ms on c3cb001f81d0 (executor driver) (107/137)
[2026-03-16T02:30:10.273+0000] {subprocess.py:93} INFO - 26/03/16 02:30:10 INFO TaskSetManager: Finished task 114.0 in stage 0.0 (TID 114) in 54 ms on c3cb001f81d0 (executor driver) (108/137)
[2026-03-16T02:30:10.274+0000] {subprocess.py:93} INFO - 26/03/16 02:30:10 INFO Executor: Running task 127.0 in stage 0.0 (TID 127)
